Workbook

Sheet รายชื่อพนักงานลาออกพ้นสภาพ
A1: ลำดับ | B1: รหัสพนักงาน | C1: ชื่อ - สกุล | D1: ตำแหน่ง | E1: แผนก | F1: E-Mail | G1: ทำงานวันสุดท้าย ( วัน-เดือน-ปี ) | H1: วันที่พ้นสภาพ ( วัน-เดือน-ปี ) | I1: สถานะการลาออก/พ้นสภาพ | J1: สถานะการตรวจสอบเอกสาร | K1: สถานะการปิดลาออกจาก HR Online | L1: ปัจจัยการลาออก (For Report) | M1: เหตุผลการลาออก | N1: ลบข้อมูล Email | O1: ลบข้อมูลระบบ REM | P1: ลบข้อมูลระบบ CMS
A2: 838 | B2: BK650037 | C2: นายกษมา ชาญวิบูลย์ | D2: 8659 พนักงานขับรถส่วนกลาง | E2: แผนกยานพาหนะ | F2: kasamac@sena.co.th | I2: ยกเลิกลาออก | J2: ส่งเอกสารถึงพนักงาน | L2: ปัจจัยที่ 2 ความสัมพันธ์และบุคคลากรในองค์กร
A3: 898 | B3: ???? | C3: ???? | I3: ลาออก | J3: ส่งเอกสารถึงพนักงาน
A4: 1046 | B4: BK680355 | C4: นายวิทยา จงบรรจบ | D4: 7501 โฟร์แมนควบคุมงาน | E4: นิช โมโน เมกะ สเปซ บางนา | F4: witthayaj@sena.co.th | G4: 46081 | H4: 46082 | I4: ลาออก | J4: ส่งเอกสารถึงพนักงาน | K4: ปิดลาออกแล้ว | L4: ปัจจัยที่ 2 ความสัมพันธ์และบุคคลากรในองค์กร
A5: 1079 | B5: BK680275 | C5: นายปวเรศ ปัญจศิลป์ | D5: 7406 เจ้าหน้าที่สนับสนุนการตลาด | E5: แผนกการตลาดบ้าน 1C | F5: pavaretp@sena.co.th | G5: 46022 | H5: 46023 | I5: ลาออก | J5: ได้รับเอกสารแล้ว | K5: ปิดลาออกแล้ว | L5: ปัจจัยที่ 3 งานในหน้าที่
A6: 1082 | B6: SSG | I6: ยกเลิกลาออก
A7: 1092 | B7: VMS680102 | C7: นางสาวชิรัชยา สุรรัตน์ | D7: 5859 ผู้จัดการอาคาร | E7: แผนกอาคารชุด เสนาคิทท์ พหลโยธิน - นวนคร เฟส 1 | F7: chiratchayas@senxgroup.com | G7: 46022 | H7: 46023 | I7: ยกเลิกลาออก | J7: ส่งเอกสารถึงพนักงาน
A8: 1101 | B8: BK680400 | C8: นายดนัยเดช สวายประโคน | D8: 5555 วิศวกรไฟฟ้า | E8: เสนาคิทท์ สำโรง อินเตอร์เชนจ์ | F8: danaydechs@sena.co.th | G8: 46022 | H8: 46023 | I8: ลาออก | J8: ได้รับเอกสารแล้ว | K8: ปิดลาออกแล้ว | L8: ปัจจัยที่ 5 โอกาสในการเติบโต/พัฒนา
A9: 1130 | B9: VMS680318 | C9: นางสาวกนกวรรณ แห้วดี | D9: 6759 เจ้าหน้าที่บัญชีปิดงบอาวุโส | E9: ฝ่ายบัญชีและการเงิน | F9: kanokwanh@senxgroup.com | G9: 46022 | H9: 46023 | I9: ลาออก | J9: ได้รับเอกสารแล้ว | K9: ปิดลาออกแล้ว | L9: ปัจจัยที่ 3 งานในหน้าที่ | M9: รายละเอียดค่อนข้างเยอะ มีความซับซ้อนต้องใช้เวลา และมีกำหนดส่งงานที่ค่อนข้างกระชันชิดในแต่ละเดือน
A10: 1131 | B10: BK680590 | C10: น.ส.นันทิภา รัตนมาตย์ | D10: 7504 เจ้าหน้าที่ธุรการโครงการ | E10: โคซี่ รามอินทรา - คู้บอน | F10: nuntipar@sena.co.th | G10: 46022 | H10: 46023 | I10: ลาออก | J10: ได้รับเอกสารแล้ว | K10: ปิดลาออกแล้ว | L10: ปัจจัยที่ 6 ความจำเป็นส่วนตัว
A11: 1142 | B11: BK680637 | C11: นายพิฆเนศ ถาวรพงศ์สถิต | D11: 6401 เจ้าหน้าที่ขายและสินเชื่ออาวุโส | E11: เสนา วิลเลจ รามอินทรา กม.9 | F11: pikanatet@sena.co.th | G11: 46022 | H11: 46023 | I11: ลาออก | J11: ได้รับเอกสารแล้ว | K11: ปิดลาออกแล้ว | L11: ปัจจัยที่ 7 Probation (ไม่ผ่านทดลองงาน)
A12: 1143 | B12: VMS670135 | C12: นายวิณัฐ โภคา | D12: 8857 ช่างเทคนิค | E12: แผนกอาคารชุด เดอะ ทรี อินเตอร์เชนจ์ | F12: winutp@senxgroup.com | G12: 46022 | H12: 46023 | I12: ลาออก | J12: ได้รับเอกสารแล้ว | K12: ปิดลาออกแล้ว | L12: ปัจจัยที่ 9 เหตุผลอื่น ๆ | M12: หมดสัญญาบริหารโครงการ
A13: 1144 | B13: BK600104 | C13: น.ส.อนันตญา มินตา | D13: 4563 วิศวกรประมาณราคาอาวุโส | E13: แผนกสถาปัตย์คอนโด 1,2 | F13: anantayam@sena.co.th | G13: 46022 | H13: 46023 | I13: ลาออก | J13: ได้รับเอกสารแล้ว | K13: ปิดลาออกแล้ว | L13: ปัจจัยที่ 6 ความจำเป็นส่วนตัว | M13: ประกอบธุรกิจส่วนตัวกับครอบครัวที่ชลบุรี เป็นผู้รับเหมา
A14: 1145 | B14: BK680561 | C14: น.ส.สุพัฒตรา พุ่มจิ๋ว | D14: 7504 เจ้าหน้าที่ธุรการโครงการ | E14: เสนาคิทท์ บางนา - ก.ม.29 เฟส 1,2 | F14: Suphattrap@sena.co.th | G14: 46022 | H14: 46023 | I14: ลาออก | J14: ได้รับเอกสารแล้ว | K14: ปิดลาออกแล้ว | L14: ปัจจัยที่ 4 องค์กร
A15: 1148 | B15: BK680564 | C15: น.ส.เขมจิรา บุญคำ | D15: 8501 พนักงานธุรการโครงการ | E15: เสนา พาร์ค แกรนด์ รามอินทรา เฟส 2 | F15: Khemjirab@sena.co.th | G15: 46142 | H15: 46143 | I15: ลาออก | J15: ได้รับเอกสารแล้ว | K15: ปิดลาออกแล้ว | L15: ปัจจัยที่ 6 ความจำเป็นส่วนตัว
A16: 1151 | B16: VMS680181 | C16: นางสาวณัฐวรรณ ศิริปรุ | D16: 7853 เจ้าหน้าที่บัญชีนิติบุคคล | E16: แผนกบัญชีแนวราบ | F16: nattawans@senxgroup.com | G16: 46022 | H16: 46023 | I16: ลาออก | J16: ได้รับเอกสารแล้ว | K16: ปิดลาออกแล้ว | L16: ปัจจัยที่ 1 ผลตอบแทนการทำงาน | M16: 1.ต้องทำงานของคนเก่าที่ลาออกไม่ได้ต่องานกันซึ่งทำงานให้งานมีที่มีอยู่ปัจจุบันปิดงบไม่ทัน 2. ได้งานใหม่เงินเดือนเพิ่มจากเดิม 5,000 บาท
A17: 1153 | B17: VMS680078 | C17: นางสาวณัฐชนท เรืองทรัพย์บำรุง | D17: 5754 ผู้ช่วยหัวหน้าแผนกบัญชีลูกหนี้ | E17: แผนกการเงินรับ | F17: natchanontr@senxgroup.com | G17: 46022 | H17: 46023 | I17: ลาออก | J17: ได้รับเอกสารแล้ว | K17: ปิดลาออกแล้ว | L17: ปัจจัยที่ 6 ความจำเป็นส่วนตัว | M17: เนื่องจากต้องกลับย้ายกลับไปอยู่บ้านต่างจังหวัดกำแพงเพชร ทำธุรกิจส่วนตัวทำขนมขาย
A18: 1154 | B18: VMS670136 | C18: นายเทิดศักดิ์ ขันโอฬาร | D18: 8857 ช่างเทคนิค | E18: แผนกอาคารชุด เดอะ ทรี อินเตอร์เชนจ์ | F18: terdsakk@senxgroup.com | G18: 46022 | H18: 46023 | I18: ลาออก | J18: ได้รับเอกสารแล้ว | K18: ปิดลาออกแล้ว | L18: ปัจจัยที่ 9 เหตุผลอื่น ๆ | M18: หมดสัญญาบริหารโครงการ
A19: 1159 | B19: VMS680145 | C19: นายอานนท์ เส้งคล้าย | D19: 7855 หัวหน้าช่างประจำอาคาร | E19: แผนกอาคารชุด ไอ-เฮาส์ ลากูน่า การ์เด้น | F19: arnons@senxgroup.com | G19: 46022 | H19: 46023 | I19: ลาออก | J19: ได้รับเอกสารแล้ว | K19: ปิดลาออกแล้ว | L19: ปัจจัยที่ 1 ผลตอบแทนการทำงาน | M19: ได้งานใหม่ บริษัท ลีฟ อัลติเมท แวลูส์ จำกัด เงินเดือนเพิ่มขึ้น 7,000 บาท ดูโครงการห้องจำนวน 1,400 ห้อง
A20: 1160 | B20: BK680219 | C20: น.ส.ฤชาลักษณ์ จิตอารี | D20: 33 ผู้จัดการ | E20: ฝ่ายบริหารการขายคอนโด 4A | F20: luachaluckj@sena.co.th | G20: 46022 | H20: 46023 | I20: ลาออกไม่ครบ 30 วัน | J20: ได้รับเอกสารแล้ว | K20: ปิดลาออกแล้ว
A21: 1162 | B21: VMS680109 | C21: นายเศรษฐวุฒิ สอนง่าย | D21: 8855 ช่างประจำอาคาร | E21: แผนกอาคารชุด เสนาคิทท์ รังสิต - ติวานนท์ | F21: sethtawuts@senxgroup.com | G21: 46022 | H21: 46023 | I21: ลาออกไม่ครบ 30 วัน | J21: ได้รับเอกสารแล้ว | K21: ปิดลาออกแล้ว | L21: ปัจจัยที่ 1 ผลตอบแทนการทำงาน | M21: ได้งานใหม่เงินเดือนเพิ่ม จากเดิม 2,000 บาทและเลื่อนตำแหน่งจาก Officer เป็น Senior ทำงานกับบริษัท โนเบิ้ล
A22: 1165 | B22: VMS680329 | C22: นางสาวดวงธิดา วัฒนกุล | D22: 7854 เจ้าหน้าที่นิติบุคคล | E22: แผนกอาคารชุด โชคชัยร่วมมิตร คอนโด | F22: duangtidaw@senxgroup.com | G22: 46022 | H22: 46023 | I22: ลาออกไม่ครบ 30 วัน | J22: ได้รับเอกสารแล้ว | K22: ปิดลาออกแล้ว | L22: ปัจจัยที่ 6 ความจำเป็นส่วนตัว | M22: ทำธุรกิจกับครอบครัวเปิดร้านกาแฟ
A23: 1166 | B23: VMS680184 | C23: นายพะเยาว์ พุทธสีมา | D23: 8855 ช่างประจำอาคาร | E23: แผนกอาคารชุด นิช โมโน รามคำแหง | F23: payaop@senxgroup.com | G23: 46022 | H23: 46023 | I23: ลาออก | J23: ได้รับเอกสารแล้ว | K23: ปิดลาออกแล้ว | L23: ปัจจัยที่ 6 ความจำเป็นส่วนตัว | M23: ไปทำธุรกิจประเภทรับเหมาก่อสร้าง
A24: 1168 | B24: VMS680237 | C24: นายอุทิศ สุจำนงค์ | D24: 8855 ช่างประจำอาคาร | E24: แผนกอาคารชุด แมเนอร์ สนามบินน้ำ | F24: autids@senxgroup.com | G24: 46022 | H24: 46023 | I24: ลาออก | K24: ปิดลาออกแล้ว
A25: 1172 | B25: VMS670037 | C25: นายจักรกฤษ์ ธรรมวงศ์ | D25: 8855 ช่างประจำอาคาร | E25: แผนกอาคารชุด เวรี่ ลาซาล สุขุมวิท 105 | F25: jukkritt@senxgroup.com | G25: 46022 | H25: 46023 | I25: ลาออกไม่ครบ 30 วัน | J25: ได้รับเอกสารแล้ว | K25: ปิดลาออกแล้ว | L25: ปัจจัยที่ 1 ผลตอบแทนการทำงาน | M25: เหตุผลเนื่องจากผ่านมาไม่มีการปรับเงินเดือน ทำให้ตัดสินใจลาออก
A26: 1173 | B26: VMS680183 | C26: นายพีรพัฒน์ อภัยพิพัฒน์ | D26: 8855 ช่างประจำอาคาร | E26: แผนกอาคารชุด แอทโมซ รัชดา - ห้วยขวาง | F26: peerapata@senxgroup.com | G26: 46030 | H26: 46031 | I26: ยกเลิกลาออก | M26: เหตุุผลที่ลาออกเนื่องจาก ติดเรียนวันเสาร์- อาทิตย์
A27: 1178 | B27: BK670055 | C27: น.ส.รัชนีกร แพงทรัพย์ | D27: 7759 เจ้าหน้าที่บัญชีปิดงบ | E27: แผนกบัญชีต้นทุน | F27: ratchaneekornp@sena.co.th | G27: 46053 | H27: 46054 | I27: ลาออก | J27: ได้รับเอกสารแล้ว | K27: ปิดลาออกแล้ว | L27: ปัจจัยที่ 5 โอกาสในการเติบโต/พัฒนา
A28: 1179 | B28: VMS680130 | C28: นายรัตนชัย พลช่วย | D28: 8855 ช่างประจำอาคาร | E28: แผนกอาคารชุด เสนาคิทท์ เทพารักษ์ - บางบ่อ 2 | F28: rattanachaip@senxgroup.com | G28: 46037 | H28: 46038 | I28: ลาออก | J28: ได้รับเอกสารแล้ว | K28: ปิดลาออกแล้ว | L28: ปัจจัยที่ 6 ความจำเป็นส่วนตัว | M28: กลับบ้านต่างจังหวัดไปดูแลพ่อที่ป่วยเนื่องจากพิษราเดินไม่ได้ตอนนี้รักษาตัวอยู่ที่โรงพยาบาล
A29: 1180 | B29: VMS680113 | C29: นางสาวกุสุมา เล้าสูงเนิน | D29: 7853 เจ้าหน้าที่บัญชีนิติบุคคล | E29: แผนกการเงินจ่าย | F29: kusumal@senxgroup.com | G29: 46037 | H29: 46038 | I29: ลาออก | J29: ได้รับเอกสารแล้ว | K29: ปิดลาออกแล้ว | L29: ปัจจัยที่ 3 งานในหน้าที่ | M29: เหตุผลเนื่องจากขั้นตอนการทำงานที่ซับซ้อน ปรับเปลี่ยนตลอดทำให้งานที่ทำวนไปวนมา เหมือนการทำงานไม่มี Flow การทำงาน และ ได้งานใหม่ซึ่งที่ใหม่ให้เดือนเพิ่ม 5,000 บาท + เงินค่าไม่สาย ไม่ลา ไม่ขาดงาน อีก 1,000 บาท
A30: 1181 | B30: VMS670162 | C30: นางสาววิภารัตน์ ตระกูลสัมพันธ์ | D30: 7504 เจ้าหน้าที่ธุรการโครงการ | E30: แผนกอาคารชุด เดอะ เชดด์ สาทร 1 | F30: wiparattr@senxgroup.com | G30: 46045 | H30: 46046 | I30: ลาออก | J30: ได้รับเอกสารแล้ว | K30: ปิดลาออกแล้ว | L30: ปัจจัยที่ 6 ความจำเป็นส่วนตัว | M30: เนื่องจากต้องย้ายไปอยู่ต่างจังหวัดกับพี่สาวที่ชลบุรี และ ต้องการทำงานในรูปแบบ Office ทำงาน 5 วัน ได้หยุดเสาร์ - อาทิตย์
A31: 1183 | B31: BK680663 | C31: น.ส.กิรณา ครองศิริ | D31: 7401 เจ้าหน้าที่ขายและสินเชื่อ | E31: นิช โมโน บางโพ | F31: kiranak@sena.co.th | G31: 46040 | H31: 46041 | I31: ลาออกไม่ครบ 30 วัน | J31: ได้รับเอกสารแล้ว | K31: ปิดลาออกแล้ว | L31: ปัจจัยที่ 2 ความสัมพันธ์และบุคคลากรในองค์กร
A32: 1185 | B32: VMS620164 | C32: นางสาวปนัดดา อยู่แขก | D32: 5859 ผู้จัดการอาคาร | E32: แผนกอาคารชุด เวนโต้ คอนโด เกษตร นวมินทร์ | F32: panadday@senxgroup.com | G32: 46023 | H32: 46024 | I32: ยกเลิกลาออก
A33: 1186 | B33: VMS680278 | C33: นายสิรวิชญ์ หวังสมนึก | D33: 8855 ช่างประจำอาคาร | E33: แผนกอาคารชุด เวรี่ ลาซาล สุขุมวิท 105 | F33: sirawitw@senxgroup.com | G33: 46037 | H33: 46038 | I33: ลาออก | J33: ได้รับเอกสารแล้ว | K33: ปิดลาออกแล้ว | L33: ปัจจัยที่ 7 Probation (ไม่ผ่านทดลองงาน) | M33: ไม่ผ่านทดลองงาน
A34: 1187 | B34: VMS680301 | C34: นายศุภชัย มานะผล | D34: 8855 ช่างประจำอาคาร | E34: แผนกอาคารชุด เวรี่ ลาซาล สุขุมวิท 105 | F34: supachaim@senxgroup.com | G34: 46053 | H34: 46054 | I34: ลาออก | J34: ได้รับเอกสารแล้ว | K34: ปิดลาออกแล้ว | L34: ปัจจัยที่ 7 Probation (ไม่ผ่านทดลองงาน) | M34: ไม่ผ่านทดลองงาน
A35: 1188 | B35: VMS670300 | C35: นางสาวศิริพรรณ จิตรชัยภูมิ | D35: 7854 เจ้าหน้าที่นิติบุคคล | E35: แผนกอาคารชุด นิช โมโน พระราม 9 | F35: siripunj@senxgroup.com | G35: 46030 | H35: 46031 | I35: ลาออกไม่ครบ 30 วัน | J35: ได้รับเอกสารแล้ว | K35: ปิดลาออกแล้ว | L35: ปัจจัยที่ 1 ผลตอบแทนการทำงาน | M35: ได้งานที่ใหม่เดินทางใกล้บ้าน เงินเดือนเพิ่มจากเดิม 1,500 บาท ทำงานไม่มีปัญหา
A36: 1189 | B36: VMS680177 | C36: นายพิพัฒพงษ์ ชัยสุวรรณ | D36: 8855 ช่างประจำอาคาร | E36: แผนกอาคารชุด แอทโมซ รัชดา - ห้วยขวาง | F36: pipatpongc@senxgroup.com | G36: 46027 | H36: 46028 | I36: ลาออกไม่ครบ 30 วัน | K36: ปิดลาออกแล้ว | L36: ปัจจัยที่ 1 ผลตอบแทนการทำงาน | M36: ได้งานใหม่ทำในตำแหน่งธุรการจัดซื้อ เป็นโรงงานจะมี OT ซึ่งได้เงินเดือนเพิ่มจากเดิม 2,500 บาท
A37: 1190 | B37: SX680017 | C37: นางสาวปุณยนุช สืบนุกูล | D37: 7754 เจ้าหน้าที่บัญชีลูกหนี้ | E37: แผนกบัญชีลูกหนี้ | F37: poonyanuchs@senxgroup.com | G37: 46022 | H37: 46023 | I37: ลาออกไม่ครบ 30 วัน | K37: ปิดลาออกแล้ว | L37: ปัจจัยที่ 7 Probation (ไม่ผ่านทดลองงาน) | M37: ไม่ผ่านทดลองงาน
A38: 1191 | B38: BK680553 | C38: น.ส.ดวงจันทร์ วงทองนิล | D38: 7504 เจ้าหน้าที่ธุรการโครงการ | E38: เสนา วิลล์ ลำลูกกา - คลอง 6 | F38: duangjanw@sena.co.th | G38: 46053 | H38: 46054 | I38: ลาออก | J38: ได้รับเอกสารแล้ว | K38: ปิดลาออกแล้ว | L38: ปัจจัยที่ 6 ความจำเป็นส่วนตัว
A39: 1192 | B39: BK680394 | C39: นายสุรกานต์ หาญตระกูล | D39: 5501 วิศวกรสนาม | E39: เสนาคิทท์ สำโรง อินเตอร์เชนจ์ | F39: surakanh@sena.co.th | G39: 46053 | H39: 46054 | I39: ลาออก | J39: ได้รับเอกสารแล้ว | K39: ปิดลาออกแล้ว | L39: ปัจจัยที่ 1 ผลตอบแทนการทำงาน
A40: 1193 | B40: BK680654 | C40: นายพิชชากร ชอุ่มผล | D40: 6401 เจ้าหน้าที่ขายและสินเชื่ออาวุโส | E40: เสนา วิลเลจ บางนา - กม.29 | F40: pichchakornc@sena.co.th | G40: 46022 | H40: 46023 | I40: ลาออกไม่ครบ 30 วัน | J40: ต้นสังกัดแจ้งทางเมล์ | K40: ปิดลาออกแล้ว
...

Sheet เลขที่เอกสารใบลาออก
A1: วันที่ | B1: รหัสพนักงาน | C1: ชื่อนามสกุล | D1: ตำแหน่ง | E1: ฝ่าย/แผนก | F1: วันที่พ้นสภาพ | G1: เลขที่เอกสารใบลาออก | H1: เลขที่เอกสาร Sena D | I1: เลขที่เอกสาร Sen X | J1: เลขที่เอกสาร Sena Green
A2: 45304 | B2: SD660001 | C2: นางสาวกาญจนา เทวกุล | D2: 21 ผู้อำนวยการอาวุโส | E2: สายงาน Brand & Strategic Communication | F2: 45304 | G2: 2024-001 | J2: =if(IF(OR(LEFT(B2,3)="SSE",LEFT(B2,3)="ESE",LEFT(B2,3)="SGA",LEFT(B2,3)="SRF",LEFT(B2,3)="SSG",LEFT(B2,3)="SGE"),"SGE")="SGE","SG2024-"&if(counta(#REF!)-countifs(#REF!,"")+1<=9,"00"&counta(#REF!)-countifs(#REF!,"")+1,if(counta(#REF!)-countifs(#REF!,"")+1<=99,"0"&counta(#REF!)-countifs(#REF!,"")+1,counta(#REF!)-countifs(#REF!,"")+1)),"")
A3: 45323 | B3: SX670050 | C3: นายธวัช สินสิงห์ | D3: 34 ผู้จัดการโครงการ | E3: ฝ่ายก่อสร้าง 52C | F3: 45323 | G3: 2024-002 | I3: SX-2024-001 | J3: =if(IF(OR(LEFT(B3,3)="SSE",LEFT(B3,3)="ESE",LEFT(B3,3)="SGA",LEFT(B3,3)="SRF",LEFT(B3,3)="SSG",LEFT(B3,3)="SGE"),"SGE")="SGE","SG2024-"&if(counta($J$2:J2)-countifs($J$2:J2,"")+1<=9,"00"&counta($J$2:J2)-countifs($J$2:J2,"")+1,if(counta($J$2:J2)-countifs($J$2:J2,"")+1<=99,"0"&counta($J$2:J2)-countifs($J$2:J2,"")+1,counta($J$2:J2)-countifs($J$2:J2,"")+1)),"")
A4: 45352 | B4: BK660105 | C4: นางสาวกฤติยา พวงปัญญา | D4: 7759 เจ้าหน้าที่บัญชีปิดงบ | E4: แผนกบัญชีต้นทุน | F4: 45352 | G4: 2024-003 | J4: =if(IF(OR(LEFT(B4,3)="SSE",LEFT(B4,3)="ESE",LEFT(B4,3)="SGA",LEFT(B4,3)="SRF",LEFT(B4,3)="SSG",LEFT(B4,3)="SGE"),"SGE")="SGE","SG2024-"&if(counta($J$2:J3)-countifs($J$2:J3,"")+1<=9,"00"&counta($J$2:J3)-countifs($J$2:J3,"")+1,if(counta($J$2:J3)-countifs($J$2:J3,"")+1<=99,"0"&counta($J$2:J3)-countifs($J$2:J3,"")+1,counta($J$2:J3)-countifs($J$2:J3,"")+1)),"")
A5: 45367 | B5: SD650010 | C5: นายธีระวัต เกิดสุข | D5: 7155 เจ้าหน้าที่กราฟฟิค | E5: แผนก Graphic Designer | F5: 45367 | G5: 2024-004 | J5: =if(IF(OR(LEFT(B5,3)="SSE",LEFT(B5,3)="ESE",LEFT(B5,3)="SGA",LEFT(B5,3)="SRF",LEFT(B5,3)="SSG",LEFT(B5,3)="SGE"),"SGE")="SGE","SG2024-"&if(counta($J$2:J4)-countifs($J$2:J4,"")+1<=9,"00"&counta($J$2:J4)-countifs($J$2:J4,"")+1,if(counta($J$2:J4)-countifs($J$2:J4,"")+1<=99,"0"&counta($J$2:J4)-countifs($J$2:J4,"")+1,counta($J$2:J4)-countifs($J$2:J4,"")+1)),"")
A6: 45383 | B6: BK610104 | C6: อุบลทิพย์ เอกชัยเรืองเดช | D6: 6551 สถาปนิกอาวุโส | E6: แผนกพัฒนาธุรกิจและสรรหาที่ดิน | F6: 45390 | G6: 2024-005 | J6: =if(IF(OR(LEFT(B6,3)="SSE",LEFT(B6,3)="ESE",LEFT(B6,3)="SGA",LEFT(B6,3)="SRF",LEFT(B6,3)="SSG",LEFT(B6,3)="SGE"),"SGE")="SGE","SG2024-"&if(counta($J$2:J5)-countifs($J$2:J5,"")+1<=9,"00"&counta($J$2:J5)-countifs($J$2:J5,"")+1,if(counta($J$2:J5)-countifs($J$2:J5,"")+1<=99,"0"&counta($J$2:J5)-countifs($J$2:J5,"")+1,counta($J$2:J5)-countifs($J$2:J5,"")+1)),"")
A7: 45383 | B7: MMS660436 | C7: นางสาวอัยลดา กรโกษา | D7: 33 ผู้จัดการ | E7: ฝ่ายการตลาดธุรกิจ 2D | F7: 45383 | G7: 2024-006 | J7: =if(IF(OR(LEFT(B7,3)="SSE",LEFT(B7,3)="ESE",LEFT(B7,3)="SGA",LEFT(B7,3)="SRF",LEFT(B7,3)="SSG",LEFT(B7,3)="SGE"),"SGE")="SGE","SG2024-"&if(counta($J$2:J6)-countifs($J$2:J6,"")+1<=9,"00"&counta($J$2:J6)-countifs($J$2:J6,"")+1,if(counta($J$2:J6)-countifs($J$2:J6,"")+1<=99,"0"&counta($J$2:J6)-countifs($J$2:J6,"")+1,counta($J$2:J6)-countifs($J$2:J6,"")+1)),"")
A8: 45352 | B8: BK660130 | C8: นางสาวปนัดดา ศรีมาตย์ | D8: 7451 เจ้าหน้าที่สินเชื่อ | E8: ฝ่ายการตลาดธุรกิจ 2D | F8: 45352 | G8: 2024-007 | J8: =if(IF(OR(LEFT(B8,3)="SSE",LEFT(B8,3)="ESE",LEFT(B8,3)="SGA",LEFT(B8,3)="SRF",LEFT(B8,3)="SSG",LEFT(B8,3)="SGE"),"SGE")="SGE","SG2024-"&if(counta($J$2:J7)-countifs($J$2:J7,"")+1<=9,"00"&counta($J$2:J7)-countifs($J$2:J7,"")+1,if(counta($J$2:J7)-countifs($J$2:J7,"")+1<=99,"0"&counta($J$2:J7)-countifs($J$2:J7,"")+1,counta($J$2:J7)-countifs($J$2:J7,"")+1)),"")
A9: 45352 | B9: BK660144 | C9: นางสาวพิรญาณ์ พิมพา | D9: 7453 เจ้าหน้าที่ภูมิทัศน์ | E9: แผนกดูแลภูมิทัศน์ | F9: 45352 | G9: 2024-008 | J9: =if(IF(OR(LEFT(B9,3)="SSE",LEFT(B9,3)="ESE",LEFT(B9,3)="SGA",LEFT(B9,3)="SRF",LEFT(B9,3)="SSG",LEFT(B9,3)="SGE"),"SGE")="SGE","SG2024-"&if(counta($J$2:J8)-countifs($J$2:J8,"")+1<=9,"00"&counta($J$2:J8)-countifs($J$2:J8,"")+1,if(counta($J$2:J8)-countifs($J$2:J8,"")+1<=99,"0"&counta($J$2:J8)-countifs($J$2:J8,"")+1,counta($J$2:J8)-countifs($J$2:J8,"")+1)),"")
A10: 45383 | B10: BK650039 | C10: นางสาวเพ็ญพิชชา แซ่หลี | D10: 7759 เจ้าหน้าที่บัญชีปิดงบ | E10: แผนกบัญชีต้นทุน | F10: 45383 | G10: 2024-009 | J10: =if(IF(OR(LEFT(B10,3)="SSE",LEFT(B10,3)="ESE",LEFT(B10,3)="SGA",LEFT(B10,3)="SRF",LEFT(B10,3)="SSG",LEFT(B10,3)="SGE"),"SGE")="SGE","SG2024-"&if(counta($J$2:J9)-countifs($J$2:J9,"")+1<=9,"00"&counta($J$2:J9)-countifs($J$2:J9,"")+1,if(counta($J$2:J9)-countifs($J$2:J9,"")+1<=99,"0"&counta($J$2:J9)-countifs($J$2:J9,"")+1,counta($J$2:J9)-countifs($J$2:J9,"")+1)),"")
A11: 45383 | B11: VMS660042 | C11: นายนิธิพล คัมภีรพันธ์ | D11: 8855 ช่างประจำอาคาร | E11: ส่วนงานวิศวกรรม | F11: 45383 | G11: 2024-010 | I11: SX-VMS2024-001 | J11: =if(IF(OR(LEFT(B11,3)="SSE",LEFT(B11,3)="ESE",LEFT(B11,3)="SGA",LEFT(B11,3)="SRF",LEFT(B11,3)="SSG",LEFT(B11,3)="SGE"),"SGE")="SGE","SG2024-"&if(counta($J$2:J10)-countifs($J$2:J10,"")+1<=9,"00"&counta($J$2:J10)-countifs($J$2:J10,"")+1,if(counta($J$2:J10)-countifs($J$2:J10,"")+1<=99,"0"&counta($J$2:J10)-countifs($J$2:J10,"")+1,counta($J$2:J10)-countifs($J$2:J10,"")+1)),"")
A12: 45380 | B12: VMS650135 | C12: นายพุฒ กกกลิ่น | D12: 8855 ช่างประจำอาคาร | E12: ส่วนงานวิศวกรรม | F12: 45380 | G12: 2024-011 | I12: SX-VMS2024-002 | J12: =if(IF(OR(LEFT(B12,3)="SSE",LEFT(B12,3)="ESE",LEFT(B12,3)="SGA",LEFT(B12,3)="SRF",LEFT(B12,3)="SSG",LEFT(B12,3)="SGE"),"SGE")="SGE","SG2024-"&if(counta($J$2:J11)-countifs($J$2:J11,"")+1<=9,"00"&counta($J$2:J11)-countifs($J$2:J11,"")+1,if(counta($J$2:J11)-countifs($J$2:J11,"")+1<=99,"0"&counta($J$2:J11)-countifs($J$2:J11,"")+1,counta($J$2:J11)-countifs($J$2:J11,"")+1)),"")
A13: 45383 | B13: MMS660398 | C13: นางสาวภัสร์ฐิตา ตรีภพวริทธิ์ธร | D13: 6401 เจ้าหน้าที่ขายและสินเชื่ออาวุโส | E13: บ้านร่วมทางฝัน 6 ปิ่นเกล้า-บรมราชชนนี | F13: 45383 | G13: 2024-012 | J13: =if(IF(OR(LEFT(B13,3)="SSE",LEFT(B13,3)="ESE",LEFT(B13,3)="SGA",LEFT(B13,3)="SRF",LEFT(B13,3)="SSG",LEFT(B13,3)="SGE"),"SGE")="SGE","SG2024-"&if(counta($J$2:J12)-countifs($J$2:J12,"")+1<=9,"00"&counta($J$2:J12)-countifs($J$2:J12,"")+1,if(counta($J$2:J12)-countifs($J$2:J12,"")+1<=99,"0"&counta($J$2:J12)-countifs($J$2:J12,"")+1,counta($J$2:J12)-countifs($J$2:J12,"")+1)),"")
A14: 45395 | B14: BK650105 | C14: นางสาวธรรญธร โคมพันธ์ | D14: 7705 เจ้าหน้าที่โอนกรรมสิทธิ์ | E14: แผนกโอนกรรมสิทธิ์ | F14: 45395 | G14: 2024-013 | J14: =if(IF(OR(LEFT(B14,3)="SSE",LEFT(B14,3)="ESE",LEFT(B14,3)="SGA",LEFT(B14,3)="SRF",LEFT(B14,3)="SSG",LEFT(B14,3)="SGE"),"SGE")="SGE","SG2024-"&if(counta($J$2:J13)-countifs($J$2:J13,"")+1<=9,"00"&counta($J$2:J13)-countifs($J$2:J13,"")+1,if(counta($J$2:J13)-countifs($J$2:J13,"")+1<=99,"0"&counta($J$2:J13)-countifs($J$2:J13,"")+1,counta($J$2:J13)-countifs($J$2:J13,"")+1)),"")
A15: 45383 | B15: VMS660120 | C15: นายเดชา อุ่นหะวงค์ | D15: 7855 หัวหน้าช่างประจำอาคาร | E15: แผนกอาคารชุด เฟล็กซี่ เตาปูน อินเตอร์เชนจ์ | F15: 45383 | G15: 2024-014 | I15: SX-VMS2024-003 | J15: =if(IF(OR(LEFT(B15,3)="SSE",LEFT(B15,3)="ESE",LEFT(B15,3)="SGA",LEFT(B15,3)="SRF",LEFT(B15,3)="SSG",LEFT(B15,3)="SGE"),"SGE")="SGE","SG2024-"&if(counta($J$2:J14)-countifs($J$2:J14,"")+1<=9,"00"&counta($J$2:J14)-countifs($J$2:J14,"")+1,if(counta($J$2:J14)-countifs($J$2:J14,"")+1<=99,"0"&counta($J$2:J14)-countifs($J$2:J14,"")+1,counta($J$2:J14)-countifs($J$2:J14,"")+1)),"")
A16: 45383 | B16: VMS660134 | C16: นายธนวัฒน์ พิวัฒน์สมบัติ | D16: 7854 เจ้าหน้าที่นิติบุคคล | E16: แผนกอาคารชุด เฟล็กซี่ รัตนาธิเบศร์ | F16: 45383 | G16: 2024-015 | I16: SX-VMS2024-004 | J16: =if(IF(OR(LEFT(B16,3)="SSE",LEFT(B16,3)="ESE",LEFT(B16,3)="SGA",LEFT(B16,3)="SRF",LEFT(B16,3)="SSG",LEFT(B16,3)="SGE"),"SGE")="SGE","SG2024-"&if(counta($J$2:J15)-countifs($J$2:J15,"")+1<=9,"00"&counta($J$2:J15)-countifs($J$2:J15,"")+1,if(counta($J$2:J15)-countifs($J$2:J15,"")+1<=99,"0"&counta($J$2:J15)-countifs($J$2:J15,"")+1,counta($J$2:J15)-countifs($J$2:J15,"")+1)),"")
A17: 45383 | B17: BK650277 | C17: นายชัยวิชิต เจริญชัยเพชร | D17: 7705 เจ้าหน้าที่โอนกรรมสิทธิ์ | E17: แผนกโอนกรรมสิทธิ์ | F17: 45383 | G17: 2024-016 | J17: =if(IF(OR(LEFT(B17,3)="SSE",LEFT(B17,3)="ESE",LEFT(B17,3)="SGA",LEFT(B17,3)="SRF",LEFT(B17,3)="SSG",LEFT(B17,3)="SGE"),"SGE")="SGE","SG2024-"&if(counta($J$2:J16)-countifs($J$2:J16,"")+1<=9,"00"&counta($J$2:J16)-countifs($J$2:J16,"")+1,if(counta($J$2:J16)-countifs($J$2:J16,"")+1<=99,"0"&counta($J$2:J16)-countifs($J$2:J16,"")+1,counta($J$2:J16)-countifs($J$2:J16,"")+1)),"")
A18: 45383 | B18: MMS660430 | C18: นายศิร พวงธนสาร | D18: 7405 เจ้าหน้าที่การตลาด | E18: แผนกการตลาดธุรกิจ 2B | F18: 45383 | G18: 2024-017 | J18: =if(IF(OR(LEFT(B18,3)="SSE",LEFT(B18,3)="ESE",LEFT(B18,3)="SGA",LEFT(B18,3)="SRF",LEFT(B18,3)="SSG",LEFT(B18,3)="SGE"),"SGE")="SGE","SG2024-"&if(counta($J$2:J17)-countifs($J$2:J17,"")+1<=9,"00"&counta($J$2:J17)-countifs($J$2:J17,"")+1,if(counta($J$2:J17)-countifs($J$2:J17,"")+1<=99,"0"&counta($J$2:J17)-countifs($J$2:J17,"")+1,counta($J$2:J17)-countifs($J$2:J17,"")+1)),"")
A19: 45383 | B19: SX670064 | C19: นายสิทธิชัย มีสุข | D19: 7502 ช่างสำรวจ | E19: ส่วนสำรวจโครงการก่อสร้าง 52 | F19: 45383 | G19: 2024-018 | I19: SX-2024-002 | J19: =if(IF(OR(LEFT(B19,3)="SSE",LEFT(B19,3)="ESE",LEFT(B19,3)="SGA",LEFT(B19,3)="SRF",LEFT(B19,3)="SSG",LEFT(B19,3)="SGE"),"SGE")="SGE","SG2024-"&if(counta($J$2:J18)-countifs($J$2:J18,"")+1<=9,"00"&counta($J$2:J18)-countifs($J$2:J18,"")+1,if(counta($J$2:J18)-countifs($J$2:J18,"")+1<=99,"0"&counta($J$2:J18)-countifs($J$2:J18,"")+1,counta($J$2:J18)-countifs($J$2:J18,"")+1)),"")
A20: 45383 | B20: MMS670014 | C20: นางสาวรัชนีกร ผ่องใส | D20: 6402 เจ้าหน้าที่การตลาดอาวุโส | E20: แผนกการตลาดธุรกิจ 41A | F20: 45383 | G20: 2024-019 | J20: =if(IF(OR(LEFT(B20,3)="SSE",LEFT(B20,3)="ESE",LEFT(B20,3)="SGA",LEFT(B20,3)="SRF",LEFT(B20,3)="SSG",LEFT(B20,3)="SGE"),"SGE")="SGE","SG2024-"&if(counta($J$2:J19)-countifs($J$2:J19,"")+1<=9,"00"&counta($J$2:J19)-countifs($J$2:J19,"")+1,if(counta($J$2:J19)-countifs($J$2:J19,"")+1<=99,"0"&counta($J$2:J19)-countifs($J$2:J19,"")+1,counta($J$2:J19)-countifs($J$2:J19,"")+1)),"")
C21: นางสาวรุจิรา น้ำทอง | G21: 2024-020 | J21: =if(IF(OR(LEFT(B21,3)="SSE",LEFT(B21,3)="ESE",LEFT(B21,3)="SGA",LEFT(B21,3)="SRF",LEFT(B21,3)="SSG",LEFT(B21,3)="SGE"),"SGE")="SGE","SG2024-"&if(counta($J$2:J20)-countifs($J$2:J20,"")+1<=9,"00"&counta($J$2:J20)-countifs($J$2:J20,"")+1,if(counta($J$2:J20)-countifs($J$2:J20,"")+1<=99,"0"&counta($J$2:J20)-countifs($J$2:J20,"")+1,counta($J$2:J20)-countifs($J$2:J20,"")+1)),"")
A22: 45383 | B22: ELR660003 | C22: นางสาวเสาวณี สุขขำมาศ | D22: 7971 เจ้าหน้าที่ต้อนรับและบริการ | E22: แผนกอาคารชุด ปีติ สุขุมวิท 101 | F22: 45383 | G22: 2024-021 | I22: SX-ELR2024-001 | J22: =if(IF(OR(LEFT(B22,3)="SSE",LEFT(B22,3)="ESE",LEFT(B22,3)="SGA",LEFT(B22,3)="SRF",LEFT(B22,3)="SSG",LEFT(B22,3)="SGE"),"SGE")="SGE","SG2024-"&if(counta($J$2:J21)-countifs($J$2:J21,"")+1<=9,"00"&counta($J$2:J21)-countifs($J$2:J21,"")+1,if(counta($J$2:J21)-countifs($J$2:J21,"")+1<=99,"0"&counta($J$2:J21)-countifs($J$2:J21,"")+1,counta($J$2:J21)-countifs($J$2:J21,"")+1)),"")
A23: 45398 | B23: BK620192 | C23: นางสาวอนุศรา สิงห์สา | D23: 31 ผู้จัดการอาวุโส | E23: ฝ่ายจัดสรรเงินทุน | F23: 45398 | G23: 2024-022 | J23: =if(IF(OR(LEFT(B23,3)="SSE",LEFT(B23,3)="ESE",LEFT(B23,3)="SGA",LEFT(B23,3)="SRF",LEFT(B23,3)="SSG",LEFT(B23,3)="SGE"),"SGE")="SGE","SG2024-"&if(counta($J$2:J22)-countifs($J$2:J22,"")+1<=9,"00"&counta($J$2:J22)-countifs($J$2:J22,"")+1,if(counta($J$2:J22)-countifs($J$2:J22,"")+1<=99,"0"&counta($J$2:J22)-countifs($J$2:J22,"")+1,counta($J$2:J22)-countifs($J$2:J22,"")+1)),"")
A24: 45367 | B24: SP17660004 | C24: วิลาวัณย์ อุดศรี | D24: 7754 เจ้าหน้าที่บัญชีลูกหนี้ | E24: แผนกบัญชีลูกหนี้ (ร่วมทุน) | F24: 45367 | G24: 2024-023 | J24: =if(IF(OR(LEFT(B24,3)="SSE",LEFT(B24,3)="ESE",LEFT(B24,3)="SGA",LEFT(B24,3)="SRF",LEFT(B24,3)="SSG",LEFT(B24,3)="SGE"),"SGE")="SGE","SG2024-"&if(counta($J$2:J23)-countifs($J$2:J23,"")+1<=9,"00"&counta($J$2:J23)-countifs($J$2:J23,"")+1,if(counta($J$2:J23)-countifs($J$2:J23,"")+1<=99,"0"&counta($J$2:J23)-countifs($J$2:J23,"")+1,counta($J$2:J23)-countifs($J$2:J23,"")+1)),"")
A25: 45399 | B25: MMS660219 | C25: นางสาวธนัชภรณ์ พรมวาด | D25: 4401 หัวหน้างานขายและสินเชื่อ | E25: เสนาคิทท์ สาทร-กัลปพฤกษ์ | F25: 45399 | G25: 2024-024 | J25: =if(IF(OR(LEFT(B25,3)="SSE",LEFT(B25,3)="ESE",LEFT(B25,3)="SGA",LEFT(B25,3)="SRF",LEFT(B25,3)="SSG",LEFT(B25,3)="SGE"),"SGE")="SGE","SG2024-"&if(counta($J$2:J24)-countifs($J$2:J24,"")+1<=9,"00"&counta($J$2:J24)-countifs($J$2:J24,"")+1,if(counta($J$2:J24)-countifs($J$2:J24,"")+1<=99,"0"&counta($J$2:J24)-countifs($J$2:J24,"")+1,counta($J$2:J24)-countifs($J$2:J24,"")+1)),"")
A26: 45383 | B26: MMS650142 | C26: นางสาวรัฐติกรณ์ ฤทธิ์ประเสริฐ | D26: 6401 เจ้าหน้าที่ขายและสินเชื่ออาวุโส | E26: เสนา คิทท์ เพชรเกษม-พุทธมณฑลสาย 7 | F26: 45383 | G26: 2024-025 | J26: =if(IF(OR(LEFT(B26,3)="SSE",LEFT(B26,3)="ESE",LEFT(B26,3)="SGA",LEFT(B26,3)="SRF",LEFT(B26,3)="SSG",LEFT(B26,3)="SGE"),"SGE")="SGE","SG2024-"&if(counta($J$2:J25)-countifs($J$2:J25,"")+1<=9,"00"&counta($J$2:J25)-countifs($J$2:J25,"")+1,if(counta($J$2:J25)-countifs($J$2:J25,"")+1<=99,"0"&counta($J$2:J25)-countifs($J$2:J25,"")+1,counta($J$2:J25)-countifs($J$2:J25,"")+1)),"")
A27: 45371 | B27: VMS660103 | C27: นายสนิท อินประภัทตร์ | D27: 8855 ช่างประจำอาคาร | E27: แผนกวิศวกรรมส่วนกลาง | F27: 45371 | G27: 2024-026 | I27: SX-VMS2024-005 | J27: =if(IF(OR(LEFT(B27,3)="SSE",LEFT(B27,3)="ESE",LEFT(B27,3)="SGA",LEFT(B27,3)="SRF",LEFT(B27,3)="SSG",LEFT(B27,3)="SGE"),"SGE")="SGE","SG2024-"&if(counta($J$2:J26)-countifs($J$2:J26,"")+1<=9,"00"&counta($J$2:J26)-countifs($J$2:J26,"")+1,if(counta($J$2:J26)-countifs($J$2:J26,"")+1<=99,"0"&counta($J$2:J26)-countifs($J$2:J26,"")+1,counta($J$2:J26)-countifs($J$2:J26,"")+1)),"")
A28: 45400 | B28: MMS660312 | C28: นางสาวปาลญา อัศวะลาภา | D28: 6401 เจ้าหน้าที่ขายและสินเชื่ออาวุโส | E28: เสนาคิทท์ สาทร-กัลปพฤกษ์ | F28: 45400 | G28: 2024-027 | J28: =if(IF(OR(LEFT(B28,3)="SSE",LEFT(B28,3)="ESE",LEFT(B28,3)="SGA",LEFT(B28,3)="SRF",LEFT(B28,3)="SSG",LEFT(B28,3)="SGE"),"SGE")="SGE","SG2024-"&if(counta($J$2:J27)-countifs($J$2:J27,"")+1<=9,"00"&counta($J$2:J27)-countifs($J$2:J27,"")+1,if(counta($J$2:J27)-countifs($J$2:J27,"")+1<=99,"0"&counta($J$2:J27)-countifs($J$2:J27,"")+1,counta($J$2:J27)-countifs($J$2:J27,"")+1)),"")
A29: 45413 | B29: VMS620065 | C29: นายประชา สมจิตร์ | D29: 6856 หัวหน้าช่างประจำอาคารอาวุโส | E29: แผนกพัฒนางานบริหารอาคาร (Start Up) | F29: 45413 | G29: 2024-029 | I29: SX-VMS2024-006 | J29: =if(IF(OR(LEFT(B29,3)="SSE",LEFT(B29,3)="ESE",LEFT(B29,3)="SGA",LEFT(B29,3)="SRF",LEFT(B29,3)="SSG",LEFT(B29,3)="SGE"),"SGE")="SGE","SG2024-"&if(counta($J$2:J28)-countifs($J$2:J28,"")+1<=9,"00"&counta($J$2:J28)-countifs($J$2:J28,"")+1,if(counta($J$2:J28)-countifs($J$2:J28,"")+1<=99,"0"&counta($J$2:J28)-countifs($J$2:J28,"")+1,counta($J$2:J28)-countifs($J$2:J28,"")+1)),"")
A30: 45413 | B30: SX660026 | C30: นายสุภกิณห์ ภัทรมั่นคงสกุล | D30: 7755 เจ้าหน้าที่บัญชีต้นทุน | E30: แผนกบัญชีต้นทุน | F30: 45413 | G30: 2024-030 | I30: SX-2024-003 | J30: =if(IF(OR(LEFT(B30,3)="SSE",LEFT(B30,3)="ESE",LEFT(B30,3)="SGA",LEFT(B30,3)="SRF",LEFT(B30,3)="SSG",LEFT(B30,3)="SGE"),"SGE")="SGE","SG2024-"&if(counta($J$2:J29)-countifs($J$2:J29,"")+1<=9,"00"&counta($J$2:J29)-countifs($J$2:J29,"")+1,if(counta($J$2:J29)-countifs($J$2:J29,"")+1<=99,"0"&counta($J$2:J29)-countifs($J$2:J29,"")+1,counta($J$2:J29)-countifs($J$2:J29,"")+1)),"")
A31: 45413 | B31: BK660035 | C31: นายภูวเดช อีศรัตน์ | D31: เจ้าหน้าที่อาวุโส | E31: แผนกสินเชื่อ 1 | F31: 45413 | G31: 2024-031 | J31: =if(IF(OR(LEFT(B31,3)="SSE",LEFT(B31,3)="ESE",LEFT(B31,3)="SGA",LEFT(B31,3)="SRF",LEFT(B31,3)="SSG",LEFT(B31,3)="SGE"),"SGE")="SGE","SG2024-"&if(counta($J$2:J30)-countifs($J$2:J30,"")+1<=9,"00"&counta($J$2:J30)-countifs($J$2:J30,"")+1,if(counta($J$2:J30)-countifs($J$2:J30,"")+1<=99,"0"&counta($J$2:J30)-countifs($J$2:J30,"")+1,counta($J$2:J30)-countifs($J$2:J30,"")+1)),"")
A32: 45413 | B32: SP18660003 | C32: นางสาวกนกทิพย์ แก้วสียา | D32: 7759 เจ้าหน้าที่บัญชีปิดงบ | E32: แผนกบัญชีงบการเงิน (ร่วมทุน) | F32: 45413 | G32: 2024-032 | J32: =if(IF(OR(LEFT(B32,3)="SSE",LEFT(B32,3)="ESE",LEFT(B32,3)="SGA",LEFT(B32,3)="SRF",LEFT(B32,3)="SSG",LEFT(B32,3)="SGE"),"SGE")="SGE","SG2024-"&if(counta($J$2:J31)-countifs($J$2:J31,"")+1<=9,"00"&counta($J$2:J31)-countifs($J$2:J31,"")+1,if(counta($J$2:J31)-countifs($J$2:J31,"")+1<=99,"0"&counta($J$2:J31)-countifs($J$2:J31,"")+1,counta($J$2:J31)-countifs($J$2:J31,"")+1)),"")
A33: 45398 | B33: BK610009 | C33: นายศุภกร ศรีวิเศษ | D33: 7551 สถาปนิก | E33: แผนก DESIGN DEVELOP | F33: 45398 | G33: 2024-033 | J33: =if(IF(OR(LEFT(B33,3)="SSE",LEFT(B33,3)="ESE",LEFT(B33,3)="SGA",LEFT(B33,3)="SRF",LEFT(B33,3)="SSG",LEFT(B33,3)="SGE"),"SGE")="SGE","SG2024-"&if(counta($J$2:J32)-countifs($J$2:J32,"")+1<=9,"00"&counta($J$2:J32)-countifs($J$2:J32,"")+1,if(counta($J$2:J32)-countifs($J$2:J32,"")+1<=99,"0"&counta($J$2:J32)-countifs($J$2:J32,"")+1,counta($J$2:J32)-countifs($J$2:J32,"")+1)),"")
A34: 45413 | B34: MMS650047 | C34: นางสาวธนกร ใหม่จันทร์ | D34: 5101 ผู้ช่วยหัวหน้าแผนก | E34: แผนกการตลาดธุรกิจ 12 | F34: 45413 | G34: 2024-034 | J34: =if(IF(OR(LEFT(B34,3)="SSE",LEFT(B34,3)="ESE",LEFT(B34,3)="SGA",LEFT(B34,3)="SRF",LEFT(B34,3)="SSG",LEFT(B34,3)="SGE"),"SGE")="SGE","SG2024-"&if(counta($J$2:J33)-countifs($J$2:J33,"")+1<=9,"00"&counta($J$2:J33)-countifs($J$2:J33,"")+1,if(counta($J$2:J33)-countifs($J$2:J33,"")+1<=99,"0"&counta($J$2:J33)-countifs($J$2:J33,"")+1,counta($J$2:J33)-countifs($J$2:J33,"")+1)),"")
A35: 45413 | B35: BK660002 | C35: นางสาวแพรพลอย สุขสุทอง | D35: 7601 เจ้าหน้าที่จัดซื้อ | E35: แผนกจัดซื้อแนวสูง | F35: 45413 | G35: 2024-035 | J35: =if(IF(OR(LEFT(B35,3)="SSE",LEFT(B35,3)="ESE",LEFT(B35,3)="SGA",LEFT(B35,3)="SRF",LEFT(B35,3)="SSG",LEFT(B35,3)="SGE"),"SGE")="SGE","SG2024-"&if(counta($J$2:J34)-countifs($J$2:J34,"")+1<=9,"00"&counta($J$2:J34)-countifs($J$2:J34,"")+1,if(counta($J$2:J34)-countifs($J$2:J34,"")+1<=99,"0"&counta($J$2:J34)-countifs($J$2:J34,"")+1,counta($J$2:J34)-countifs($J$2:J34,"")+1)),"")
A36: 45413 | B36: BK670040 | C36: นางสาวยุวเทวี กลางบุรัมย์ | D36: 7659 เจ้าหน้าที่ประสานงานทั่วไป | E36: สายงาน Supply Chain Planning | F36: 45413 | G36: 2024-036 | J36: =if(IF(OR(LEFT(B36,3)="SSE",LEFT(B36,3)="ESE",LEFT(B36,3)="SGA",LEFT(B36,3)="SRF",LEFT(B36,3)="SSG",LEFT(B36,3)="SGE"),"SGE")="SGE","SG2024-"&if(counta($J$2:J35)-countifs($J$2:J35,"")+1<=9,"00"&counta($J$2:J35)-countifs($J$2:J35,"")+1,if(counta($J$2:J35)-countifs($J$2:J35,"")+1<=99,"0"&counta($J$2:J35)-countifs($J$2:J35,"")+1,counta($J$2:J35)-countifs($J$2:J35,"")+1)),"")
A37: 45413 | B37: BK650299 | C37: นางสาวปรีดาวรรณ ทัพพ่วง | D37: 23 ผู้อำนวยการ | E37: สายงานบริการลูกค้าด้านสินเชื่อ | F37: 45413 | G37: 2024-037 | J37: =if(IF(OR(LEFT(B37,3)="SSE",LEFT(B37,3)="ESE",LEFT(B37,3)="SGA",LEFT(B37,3)="SRF",LEFT(B37,3)="SSG",LEFT(B37,3)="SGE"),"SGE")="SGE","SG2024-"&if(counta($J$2:J36)-countifs($J$2:J36,"")+1<=9,"00"&counta($J$2:J36)-countifs($J$2:J36,"")+1,if(counta($J$2:J36)-countifs($J$2:J36,"")+1<=99,"0"&counta($J$2:J36)-countifs($J$2:J36,"")+1,counta($J$2:J36)-countifs($J$2:J36,"")+1)),"")
A38: 45413 | B38: VMS660034 | C38: นายภาวัช นราสินธนโชค | D38: 5859 ผู้จัดการอาคาร | E38: แผนกอาคารชุด นิช โมโน เมกะ สเปซ บางนา | F38: 45413 | G38: 2024-038 | I38: SX-VMS2024-007 | J38: =if(IF(OR(LEFT(B38,3)="SSE",LEFT(B38,3)="ESE",LEFT(B38,3)="SGA",LEFT(B38,3)="SRF",LEFT(B38,3)="SSG",LEFT(B38,3)="SGE"),"SGE")="SGE","SG2024-"&if(counta($J$2:J37)-countifs($J$2:J37,"")+1<=9,"00"&counta($J$2:J37)-countifs($J$2:J37,"")+1,if(counta($J$2:J37)-countifs($J$2:J37,"")+1<=99,"0"&counta($J$2:J37)-countifs($J$2:J37,"")+1,counta($J$2:J37)-countifs($J$2:J37,"")+1)),"")
A39: 45413 | B39: VMS650109 | C39: นายนนวัต บวรวัชรเมธี | D39: 5859 ผู้จัดการอาคาร | E39: แผนกพัฒนางานบริหารอาคาร (Start Up) | F39: 45413 | G39: 2024-039 | I39: SX-VMS2024-008 | J39: =if(IF(OR(LEFT(B39,3)="SSE",LEFT(B39,3)="ESE",LEFT(B39,3)="SGA",LEFT(B39,3)="SRF",LEFT(B39,3)="SSG",LEFT(B39,3)="SGE"),"SGE")="SGE","SG2024-"&if(counta($J$2:J38)-countifs($J$2:J38,"")+1<=9,"00"&counta($J$2:J38)-countifs($J$2:J38,"")+1,if(counta($J$2:J38)-countifs($J$2:J38,"")+1<=99,"0"&counta($J$2:J38)-countifs($J$2:J38,"")+1,counta($J$2:J38)-countifs($J$2:J38,"")+1)),"")
A40: 45413 | B40: VMS650118 | C40: นางสาวอาแอเสาะ สาแล๊ะ | D40: 7854 เจ้าหน้าที่นิติบุคคล | E40: ส่วนงานดูแลอาคาร | F40: 45413 | G40: 2024-040 | I40: SX-VMS2024-009 | J40: =if(IF(OR(LEFT(B40,3)="SSE",LEFT(B40,3)="ESE",LEFT(B40,3)="SGA",LEFT(B40,3)="SRF",LEFT(B40,3)="SSG",LEFT(B40,3)="SGE"),"SGE")="SGE","SG2024-"&if(counta($J$2:J39)-countifs($J$2:J39,"")+1<=9,"00"&counta($J$2:J39)-countifs($J$2:J39,"")+1,if(counta($J$2:J39)-countifs($J$2:J39,"")+1<=99,"0"&counta($J$2:J39)-countifs($J$2:J39,"")+1,counta($J$2:J39)-countifs($J$2:J39,"")+1)),"")
...

Sheet รายชื่อพนักงานย้ายสังกัด
E1: สังกัดเดิม | G1: --> | K1: สังกัดใหม่
A2: รหัสพนักงาน | B2: ชื่อ - สกุล | C2: ตำแหน่ง | D2: แผนก | E2: บริษัท | F2: E-Mail | H2: รหัสพนักงาน | I2: ตำแหน่ง | J2: แผนก | K2: บริษัท | L2: E-Mail | M2: วันที่มีผล
A3: SD640001 | B3: นางสาวอุมาพร ธัญลักษณ์ภาคย์ | C3: ผู้อำนวยการอาวุโส | D3: สายงาน SENA IDEA | E3: Sena Idea | F3: Umapornt@senaidea.com | H3: BK680004 | I3: ผู้อำนวยการอาวุโส | J3: สายงาน SENA IDEA | K3: Sena Development | L3: umapornt@sena.co.th
A4: SD650004 | B4: นางสาวมรรษณา แสนคำลือ | C4: เจ้าหน้าที่ประสานงานทั่วไป | D4: สายงาน SENA IDEA | E4: Sena Idea | F4: munsanas@senaidea.com | H4: BK680005 | I4: เจ้าหน้าที่ประสานงานทั่วไป | J4: สายงาน SENA IDEA | K4: Sena Development | L4: munsanas@sena.co.th
A5: SD660014 | B5: นายภาคิไนย จิตติธำรง | C5: ผู้อำนวยการอาวุโส | D5: สายงาน Digital Marketing และ Communications | E5: Sena Idea | F5: pakinain@senaidea.com | H5: BK680006 | I5: ผู้อำนวยการอาวุโส | J5: สายงาน Digital Marketing และ Communications | K5: Sena Development | L5: pakinain@sena.co.th
A6: SD670006 | B6: นางสาวอิพภา พวงหัตถ์ | C6: ผู้จัดการ | D6: ฝ่าย Digital Marketing | E6: Sena Idea | F6: ippap@senaidea.com | H6: BK680007 | I6: ผู้จัดการ | J6: ฝ่าย Digital Marketing | K6: Sena Development | L6: ippap@sena.co.th
A7: SD640021 | B7: นางสาวนัฐธิกา พรประเสริฐผล | C7: ผู้ช่วยหัวหน้าแผนก | D7: แผนก Online Media | E7: Sena Idea | F7: Nuttikap@senaidea.com | H7: BK680008 | I7: ผู้ช่วยหัวหน้าแผนก | J7: แผนก Online Media | K7: Sena Development | L7: nuttikap@sena.co.th
A8: SD640019 | B8: นางสาวสิรรัณดา จุณณะภาต | C8: ผู้ช่วยหัวหน้าแผนก | D8: แผนก Social Media Communication | E8: Sena Idea | F8: Sirarandac@senaidea.com | H8: BK680009 | I8: ผู้ช่วยหัวหน้าแผนก | J8: แผนก Social Media Communication | K8: Sena Development | L8: sirarandac@sena.co.th
A9: SD640017 | B9: นายสุรชัย พัฒเท | C9: ผู้ช่วยหัวหน้าแผนก | D9: แผนก Digital Channel และ MKT Tech | E9: Sena Idea | F9: Surachaip@senaidea.com | H9: BK680010 | I9: ผู้ช่วยหัวหน้าแผนก | J9: แผนก Digital Channel และ MKT Tech | K9: Sena Development | L9: surachaip@sena.co.th
A10: SD650003 | B10: นางสาวพรพรรณ สุทธิมล | C10: เจ้าหน้าที่ออกแบบเว็บไซด์อาวุโส | D10: แผนก Digital Channel และ MKT Tech | E10: Sena Idea | F10: pornpans@senaidea.com | H10: BK680011 | I10: เจ้าหน้าที่ออกแบบเว็บไซด์อาวุโส | J10: แผนก Digital Channel และ MKT Tech | K10: Sena Development | L10: pornpans@sena.co.th
A11: SD660010 | B11: นางสาวรัตนา ธนดำรงสิทธิ์ | C11: เจ้าหน้าที่การตลาดออนไลน์ | D11: แผนก Online Media | E11: Sena Idea | F11: rattanat@senaidea.com | H11: BK680012 | I11: เจ้าหน้าที่การตลาดออนไลน์ | J11: แผนก Online Media | K11: Sena Development | L11: rattanat@sena.co.th
A12: SD670009 | B12: นางสาววริศรา แสงคำ | C12: เจ้าหน้าที่การตลาดออนไลน์ | D12: แผนก Online Media | E12: Sena Idea | F12: warissaras@senaidea.com | H12: BK680013 | I12: เจ้าหน้าที่การตลาดออนไลน์ | J12: แผนก Online Media | K12: Sena Development | L12: warissaras@sena.co.th
A13: SDJ651002 | B13: นางสาวขนิษฐา เมืองนาค | C13: เจ้าหน้าที่การตลาดออนไลน์ | D13: แผนก Online Media | E13: Sena Idea | F13: khanittam@senaidea.com | H13: BK680014 | I13: เจ้าหน้าที่การตลาดออนไลน์ | J13: แผนก Online Media | K13: Sena Development | L13: khanittam@sena.co.th
A14: SD670010 | B14: นางสาวอภิญญา เลิศพงดี | C14: เจ้าหน้าที่ Social Media Content | D14: แผนก Social Media Communication | E14: Sena Idea | F14: apinyal@senaidea.com | H14: BK680015 | I14: เจ้าหน้าที่ Social Media Content | J14: แผนก Social Media Communication | K14: Sena Development | L14: apinyale@sena.co.th
... A44: BK670069 | B44: นางสาวลัดดาวัลย์ ปัดพรม | C44: 6660 เจ้าหน้าที่ประชาสัมพันธ์อาวุโส | D44: แผนกบริการสำนักงาน | E44: Sena Development | F44: Laddawanp@sena.co.th | H44: SX680006 | I44: 6757 เจ้าหน้าที่การเงินอาวุโส | J44: แผนกการเงิน | K44: Sen-X | L44: Laddawanp@senxgroup.com
A45: SX670044 | B45: นางสาวนันทิภา รัตนมาตย์ | C45: 7504 เจ้าหน้าที่ธุรการโครงการ | D45: เสนา วิลเลจ ติวานนท์ - บางกะดี | E45: Sen-X | F45: nuntipar@senxgroup.com | H45: BK680590 | I45: 7504 เจ้าหน้าที่ธุรการโครงการ | J45: เสนาคิทท์ ศรีนครินทร์ - ศรีด่าน | K45: Sena Development | L45: nuntipar@sena.co.th | M45: 45717
A46: SX670037 | B46: นางสาวพิมพ์ผกา วิโรจน์รัญจวน | C46: 5501 วิศวกรสนาม | D46: เสนา เวล่า รังสิต - คลอง 1 | E46: Sen-X | F46: pimpakaw@senxgroup.com | H46: BK680597 | I46: 5556 วิศวกรประมาณราคา | J46: ฝ่ายประมาณราคา และงบประมาณ | K46: Sena Development | L46: pimpakaw@sena.co.th | M46: 45748
A47: SGE660020 | B47: นายสิทธิ รัตนราษี | C47: 25 ผู้ช่วยผู้อำนวยการ | D47: สายงานบริหารทรัพยากรบุคคล | E47: Solarenergy | F47: sittir@senasolarenergy.com | H47: BK680598 | I47: 25 ผู้ช่วยผู้อำนวยการ | J47: สายงานบริหารทรัพยากรบุคคล | K47: Sena Development | L47: sittir@sena.co.th | M47: 45748
A48: BK680129 | B48: นายชัยพจน์ ช่างแต่ง | C48: 34 ผู้จัดการโครงการ | D48: สายงานจัดการระบบคุณภาพ QM | E48: Sena Development | F48: chaiyapotc@sena.co.th | H48: VMS680135 | I48: 33 ผู้จัดการ | J48: ฝ่าย Engineering | K48: Sen-X | L48: chaiyapotc@senxgroup.com | M48: 45662
A49: SSG680002 | B49: นายภูวสิษฏ์ ดอกจันทร์ | C49: 25 ผู้ช่วยผู้อำนวยการ | D49: สายงานติดตั้งและซ่อมบำรุง | E49: Solarenergy | F49: phuwasitd@senasolarenergy.com | H49: VMS680136 | I49: 25 ผู้ช่วยผู้อำนวยการ | J49: สายงาน Engineering | K49: Sen-X | L49: phuwasitd@senxgroup.com | M49: 45662
A50: SPS670030 | B50: นางสาวกัลยาณี ชุติมากุล | C50: 23 ผู้อำนวยการ | D50: สายงานขายคอนโด 2 | E50: Sen-X | F50: kanlayaneec@senxgroup.com | H50: BK680110 | I50: 23 ผู้อำนวยการ | J50: สายงานขายคอนโด 2 | K50: Sena Development | L50: kanlayaneec@sena.co.th | M50: 45658
A51: SPS670029 | B51: นางสาวอรจิรา ปัญญายง | C51: 31.1 ผู้จัดการอาวุโส | D51: นิช ไพร์ด เอกมัย | E51: Sen-X | F51: ongirap@senxgroup.com | H51: BK680111 | I51: 31.1 ผู้จัดการอาวุโส | J51: นิช ไพร์ด เอกมัย | K51: Sena Development | L51: ongirap@sena.co.th | M51: 45658 | N51: รบกวนใส่วันที่มีผลด้วยนะครับ เนื่องจากจะมีการส่ง Email แจ้งผู้ใหญ่ครับ
A52: SPS670037 | B52: นายภาณุพงศ น้อยดอนไพร | C52: 36 ผู้ช่วยผู้จัดการ | D52: นิช ไพร์ด เอกมัย | E52: Sen-X | F52: panupongn@senxgroup.com | H52: BK680112 | I52: 36 ผู้ช่วยผู้จัดการ | J52: นิช ไพร์ด เอกมัย | K52: Sena Development | L52: panupongn@sena.co.th | M52: 45658
A53: SPS670038 | B53: นางสาวธนัชชา ประทยศ | C53: 7401 เจ้าหน้าที่ขายและสินเชื่อ | D53: นิช ไพร์ด เอกมัย | E53: Sen-X | F53: thanatchap@senxgroup.com | H53: BK680113 | I53: 7401 เจ้าหน้าที่ขายและสินเชื่อ | J53: นิช ไพร์ด เอกมัย | K53: Sena Development | L53: thanatchap@sena.co.th | M53: 45658
A54: MMS660138 | B54: นายนพสิทธิ์ เตโช | C54: 23 ผู้อำนวยการ | D54: สำนักบริหารโครงการ 5 (งานก่อสร้าง) | E54: Sena MMS | F54: noppasitt@sena.co.th | H54: SX670046 | I54: 23 ผู้อำนวยการ | J54: สำนักบริหารโครงการคอนโด และบ้าน 1 (ก่อสร้าง) | K54: Sen-X | L54: noppasitt@senxgroup.com | M54: 45298
A55: BK680399 | B55: อำพล ตาเตียว | C55: ผู้ช่วยหัวหน้าแผนก | D55: เสนาคิทท์ รังสิต – คลอง 4 | E55: Sena Development | F55: ampont@sena.co.th | H55: VMS680156 | I55: ผู้ช่วยหัวหน้าแผนก | J55: สำนัักงานใหญ่ | K55: Sen-X | L55: ampont@senxgroup.com | M55: 45809
A56: BK680363 | B56: นางสาวเพ็ญนภา ชุ่มหยวก | C56: 7508 เจ้าหน้าที่สโตร์ | D56: โคซี่ รามฯ 189 สเตชั่น | E56: Sena Development | F56: pennapac@sena.co.th | H56: SGE680001 | I56: 7757 เจ้าหน้าที่การเงิน | J56: สำนัักงานใหญ่ | K56: Solarenergy | L56: pennapac@senasolarenergy.com | M56: 45809
A57: BK670027 | B57: นายภานุวัฒน์ เพชรรุ่งศักดิ์ | C57: 7804 โฟร์แมนบริการหลังการขาย | D57: ฝ่าย Sena We Care | E57: Sena Development | F57: Panuwatp@sena.co.th | H57: TK680004 | I57: 7804 โฟร์แมนบริการหลังการขาย | J57: โครงการ | K57: ทีเค นวกิจ จำกัด | L57: Panuwatp@sena.co.th | M57: 45824
A58: BK680491 | B58: นายสุภาพ ศิริวัฒนกุลวงศ์ | C58: 5505 ผู้ช่วยหัวหน้าโฟร์แมน | D58: เสนา แกรนด์โฮม บางนา กม.29 | E58: Sena Development | F58: Suphaps@sena.co.th | H58: TK680003 | I58: 5505 ผู้ช่วยหัวหน้าโฟร์แมน | J58: โครงการ | K58: ทีเค นวกิจ จำกัด | L58: Suphaps@sena.co.th | M58: 45824
A59: BK680536 | B59: นายพีรพัฒน์ อภัยพิพัฒน์ | C59: 7501 โฟร์แมนควบคุมงาน | D59: เสนา วิลเลจ บางนา - กม.29 | E59: Sena Development | F59: peerapata@sena.co.th | H59: VMS680183 | I59: 8855 ช่างประจำอาคาร | J59: แผนกอาคารชุด เดอะนิช ไพรด์ ทองหล่อ-เพชรบุรี | K59: Sen-X | L59: peerapata@senxgroup.com | M59: 45824
A60: BK680535 | B60: นายพะเยาว์ พุทธสีมา | C60: 7501 โฟร์แมนควบคุมงาน | D60: เสนา วิลเลจ บางนา - กม.29 | E60: Sena Development | F60: payaop@sena.co.th | H60: VMS680184 | I60: 8855 ช่างประจำอาคาร | J60: แผนกอาคารชุด นิช โมโน รามคำแหง | K60: Sen-X | L60: payaop@senxgroup.com | M60: 45824
A61: BK680342 | B61: นายชัยวัฒน์ ทองจำปา | C61: 7501 โฟร์แมนควบคุมงาน | D61: โคซี่ รามอินทรา - คู้บอน | E61: Sena Development | F61: chaiwatt@sena.co.th | H61: VMS680187 | I61: 8855 ช่างประจำอาคาร | J61: แผนกอาคารชุด เดอะคิทท์ พลัส พหลโยธิน-คูคต เฟส 2 | K61: Sen-X | L61: chaiwatt@senxgroup.com | M61: 45664
A62: BK680351 | B62: นายปฐมพงษ์ ด้วงนิล | C62: 7501 โฟร์แมนควบคุมงาน | D62: โคซี่ รามฯ 189 สเตชั่น | E62: Sena Development | F62: pathompongd@sena.co.th | H62: VMS680186 | I62: 8855 ช่างประจำอาคาร | J62: แผนกอาคารชุด เดอะคิทท์ พลัส พหลโยธิน-คูคต เฟส 2 | K62: Sen-X | L62: pathompongd@senxgroup.com | M62: 45664
A63: BK680438 | B63: นายวิเศษศักดิ์ พิลารักษ์ | C63: 7501 โฟร์แมนควบคุมงาน | D63: เสนา วีว่า ฉลองกรุง – ลาดกระบัง | E63: Sena Development | F63: wisetsakp@sena.co.th | H63: VMS680219 | I63: 8855 ช่างประจำอาคาร | J63: แผนกอาคารชุด นิช โมโน รามคำแหง | K63: Sen-X | L63: wisetsakp@senxgroup.com | M63: 45870
... A66: BK650192 | B66: นายชาตรี วงศ์พันธุ์ | C66: 8855 ช่างประจำอาคาร | D66: แผนกอาคารชุด เฟล็กซี่ เตาปูน อินเตอร์เชนจ์ | E66: Sena Development | F66: chatreew@sena.co.th | H66: VMS680307 | I66: 8855 ช่างประจำอาคาร | J66: แผนกวิศวกรรมโยธา | K66: Sen-X | L66: chatreewo@senxgroup.com | M66: 45931
A67: SSG680006 | B67: นายพัทธนันท์ เกตุแก้ว | C67: 7659 เจ้าหน้าที่ประสานงานทั่วไป | D67: ฝ่ายขายและการตลาด | E67: Solarenergy | F67: pattanank@senasolarenergy.com | H67: BK680661 | I67: 7659 เจ้าหน้าที่ประสานงานทั่วไปกลุ่มประธานเจ้าหน้าที่บริหาร | K67: Sena Development | L67: pattanank@sena.co.th | M67: 45962
A68: BK680634 | B68: นางสาวลลิตา ปัญสุวรรณ์ | C68: 7755 เจ้าหน้าที่บัญชีต้นทุน | D68: แผนกบัญชีต้นทุน | E68: Sena Development | F68: lalitap@sena.co.th | H68: SX680023 | I68: 7755 เจ้าหน้าที่บัญชีต้นทุน | J68: แผนกบัญชีต้นทุน | K68: Sen-X | L68: lalitap@senxgroup.com | M68: 45992
A69: VMS680307 | B69: นายชาตรี วงศ์พันธุ์ | C69: 8855 ช่างประจำอาคาร | D69: แผนกวิศวกรรมโยธา | E69: Sen-X | F69: chatreewo@senxgroup.com | H69: BK690014 | I69: 7555 โฟร์แมนตรวจคุณภาพงาน | K69: Sena Development | L69: chatreewo@sena.co.th | M69: 46023
A70: VMS680279 | B70: นายสันติภูมิ พัดทอง | C70: 7855 หัวหน้าช่างประจำอาคาร | D70: แผนกอาคารชุด นิช โมโน รามคำแหง | E70: Sen-X | F70: santiphump@senxgroup.com | H70: BK690013 | I70: 5555 วิศวกรไฟฟ้า | J70: แผนก QC | K70: Sena Development | L70: santiphump@sena.co.th | M70: 46023
A71: VT670001 | B71: นางณัฐชยา อรุณเรืองสวัสดิ์ | C71: 23 ผู้อำนวยการ | D71: สายงานบริหารธุรกิจเช่ารายย่อย (Service Apartment) | E71: เดอะ เซอร์วิส เรสซิเดนซ์ จำกัด | F71: natchayaa@sena.co.th | H71: SPS690002 | I71: 23 ผู้อำนวยการ | J71: สายงานบริหารธุรกิจเช่ารายย่อย (Service Apartment) | K71: Sen-X | L71: natchayaa@senxgroup.com | M71: 46054
...

Sheet พนักงานลาออกพ้นสภาพ(2567-2568)
A1: ลำดับ | B1: รหัสพนักงาน | C1: ชื่อ - สกุล | D1: ตำแหน่ง | E1: แผนก | F1: E-Mail | G1: ทำงานวันสุดท้าย ( ปี-เดือน-วัน ) | H1: วันที่พ้นสภาพ ( ปี-เดือน-วัน ) | I1: สถานะการลาออก/พ้นสภาพ | J1: สถานะการตรวจสอบเอกสาร | K1: สถานะการปิดลาออกจาก HR Online | L1: ปัจจัยการลาออก (For Report) | M1: เหตุผลการลาออก | N1: ลบข้อมูล Email | O1: ลบข้อมูลระบบ REM | P1: ลบข้อมูลระบบ CMS
A2: 1 | B2: MMS660105 | C2: นายธีระชัย ทาทอง | D2: 4501 วิศวกรโครงการ | E2: เสนา คิทท์ บางนา กม.29 | F2: theerachait@sena.co.th | G2: 45291 | H2: 45292 | I2: ลาออกไม่ครบ 30 วัน | J2: ยื่น Online | K2: ปิดลาออกแล้ว | L2: ปัจจัยที่ 1 ผลตอบแทนการทำงาน | N2: ลบข้อมูลแล้ว
A3: 2 | B3: MMS650434 | C3: นางสาวสุภารัตน์ กุลทะโสม | D3: 6401 เจ้าหน้าที่ขายและสินเชื่ออาวุโส | E3: นิช โมโน เมกะ สเปซ บางนา | F3: suparatk@sena.co.th | G3: 45291 | H3: 45292 | I3: ลาออก | J3: ยื่น Online | K3: ปิดลาออกแล้ว | N3: ลบข้อมูลแล้ว
A4: 3 | B4: VMS660048 | C4: นางสาวเปมิกา กระแสงแก้ว | D4: 6759 เจ้าหน้าที่บัญชีปิดงบอาวุโส | E4: ฝ่ายบัญชีนิติบุคคล 1 (คอนโด) | F4: paemikak@sena.co.th | G4: 45291 | H4: 45292 | I4: ลาออก | J4: ยื่น Online | K4: ปิดลาออกแล้ว | N4: ลบข้อมูลแล้ว
A5: 4 | B5: SP18660002 | C5: นางสาวหฤทัยรัตน์ ขวัญทอง | D5: 4101 หัวหน้าแผนก | E5: ฝ่ายบัญชีลูกหนี้ (ร่วมทุน) | F5: Haruthairatk@sena.co.th | G5: 45291 | H5: 45292 | I5: ยกเลิกลาออก | J5: ยกเลิกเอกสาร | K5: ยังไม่ปิดลาออก
A6: 5 | B6: VMS660095 | C6: นางนงนุช แสนยาสมุทร์ | D6: 5859 ผู้จัดการอาคาร | E6: นิติบุคคล เฟล็กซี่ สาทร/เจริญนคร เฟส 1 | F6: nongnuchs@sena.co.th | G6: 45291 | H6: 45292 | I6: ลาออก | J6: ยื่น Online | K6: ปิดลาออกแล้ว | N6: ลบข้อมูลแล้ว
A7: 6 | B7: SX660040 | C7: นางสาวสิริวัฒนา วิไลรัตน์ | D7: 4401 หัวหน้างานขายและสินเชื่อ | E7: ได้งานใหม่ | F7: siriwattanaw@senxgroup.com | G7: 45291 | H7: 45292 | I7: ลาออก | J7: ยื่น Online | K7: ปิดลาออกแล้ว | N7: ลบข้อมูลแล้ว
A8: 7 | B8: MMS660255 | C8: นางสาวกฤษณี คลังทรัพย์ | D8: 4401 หัวหน้างานขายและสินเชื่อ | E8: เฟล็กซี่ สำโรง อินเตอร์เชนจ์ | F8: krisneek@sena.co.th | G8: 45291 | H8: 45292 | I8: ลาออก | J8: ยื่น Online | K8: ปิดลาออกแล้ว | N8: ลบข้อมูลแล้ว
A9: 8 | B9: VMS650141 | C9: นางสาวนุศรา มะมิง | D9: 7854 เจ้าหน้าที่นิติบุคคล | E9: นิติบุคคล นิช โมโน รามคำแหง | F9: nusram@sena.co.th | G9: 45291 | H9: 45292 | I9: ลาออก | J9: ยื่น Online | K9: ปิดลาออกแล้ว | N9: ลบข้อมูลแล้ว
A10: 9 | B10: MMS660425 | C10: นางสาวอนันต์ธินี เหมือนท่าไม้ | D10: 7352 เจ้าหน้าที่ประสานงานโครงการ | E10: สำนักบริหารโครงการ 2 | F10: anantineem@sena.co.th | G10: 45291 | H10: 45292 | I10: ลาออกไม่ครบ 30 วัน | J10: ต้นสังกัดแจ้งทางเมล์ | K10: ปิดลาออกแล้ว | N10: ลบข้อมูลแล้ว
A11: 10 | B11: MMS650027 | C11: นางสำรอง ทองประเสริฐ | D11: 8656 แม่บ้านโครงการ | E11: เสนา คิทท์ พหลโยธิน/คูคต | F11: Somrongt@sena.co.th | G11: 45291 | H11: 45292 | I11: เกษียณ | J11: ไม่มีเอกสารให้ตรวจสอบ | K11: ปิดลาออกแล้ว | N11: ลบข้อมูลแล้ว
A12: 11 | B12: BK650033 | C12: นายชูเกียรติ จูมทอง | D12: 18 ผู้ช่วยกรรมการผู้จัดการ | E12: สำนักกฎหมายและนิติกรรมสัญญา | F12: chookiatj@sena.co.th | G12: 45291 | H12: 45292 | I12: ลาออก | J12: ไม่มีเอกสารให้ตรวจสอบ | K12: ปิดลาออกแล้ว | N12: ลบข้อมูลแล้ว
A13: 12 | B13: SX660052 | C13: นางสาวพิศสิณี พงษ์พิทักษ์กุล | D13: 25 ผู้ช่วยผู้อำนวยการ | E13: สายงาน Inter Sale | F13: pitsineep@senxgroup.com | G13: 45291 | H13: 45292 | I13: ลาออก | J13: ยื่น Online | K13: ปิดลาออกแล้ว | N13: ลบข้อมูลแล้ว
A14: 13 | B14: TK660011 | C14: นางสาวอรวรรณ ม่วงศรี | D14: 7804 โฟร์แมนบริการหลังการขาย | E14: แผนกซ่อมบำรุงหลังการขาย | F14: orawanm@sena.co.th | G14: 45291 | H14: 45292 | I14: ปลดออก | J14: ไม่มีเอกสารให้ตรวจสอบ | K14: ปิดลาออกแล้ว | N14: ลบข้อมูลแล้ว
A15: 14 | B15: BK650001 | C15: นายกฤษฏิ์ วัฒนโยธิน | D15: 7551 สถาปนิก | E15: แผนกพัฒนาโครงการแนวราบ | F15: kristiw@sena.co.th | G15: 45296 | H15: 45297 | I15: ลาออก | J15: ส่งเอกสารกลับไปแก้ไข | K15: ปิดลาออกแล้ว | N15: ลบข้อมูลแล้ว
A16: 15 | B16: BK650260 | C16: นายวิทยา รัตนสร้อย | D16: 7451 เจ้าหน้าที่สินเชื่อ | E16: แผนกสินเชื่อ 2 | F16: wittayar@sena.co.th | G16: 45298 | H16: 45299 | I16: ลาออก | J16: ยื่น Online | K16: ปิดลาออกแล้ว | N16: ลบข้อมูลแล้ว
A17: 16 | B17: SX670091 | C17: นางสาวกัญจน์ชญา กิติคู้จึงพัฒนา | D17: 6401 เจ้าหน้าที่ขายและสินเชื่ออาวุโส | E17: เสนา เวล่า สิริโสธร | F17: - | G17: 45299 | H17: 45300 | I17: ปลดออก | J17: ไม่มีเอกสารให้ตรวจสอบ | K17: ปิดลาออกแล้ว | N17: ลบข้อมูลแล้ว
... A34: 33 | B34: AR670187 | C34: วงศ์วิช ธันยวาท | D34: ช่างเทคนิค | E34: นิติฯ เบลกราเวีย เรสซิเดนซ์ | F34: wongwich2547@gmail.com | G34: 45315 | H34: 45316 | I34: ลาออกไม่ครบ 30 วัน | J34: ไม่มีเอกสารให้ตรวจสอบ | K34: ปิดลาออกแล้ว | N34: ลบข้อมูลแล้ว
A35: 34 | B35: AU670034 | C35: นางสาวภัคณภัทร เหมพนม | D35: 7403 เจ้าหน้าที่ขาย | E35: แผนกขายโครงการ | G35: 45296 | H35: 45297 | I35: ลาออก | J35: ได้รับเอกสารแล้ว | K35: ปิดลาออกแล้ว | N35: ลบข้อมูลแล้ว
A36: 35 | B36: AU670038 | C36: นางสาวธนภรณ์ เชิดชู | D36: 7403 เจ้าหน้าที่ขาย | E36: ฝ่ายขายและให้เช่าทั่วไป | F36: tanapron@acuterealty.com | G36: 45316 | H36: 45317 | I36: ลาออก | J36: ได้รับเอกสารแล้ว | K36: ปิดลาออกแล้ว | N36: ลบข้อมูลแล้ว
A37: 36 | B37: MMS660315 | C37: นางสาวเพียงฤทัย พรมศรี | D37: 31 ผู้จัดการอาวุโส | E37: ฝ่ายขายธุรกิจ 22 | F37: phiangruthaip@sena.co.th | G37: 45322 | H37: 45323 | I37: ลาออก | J37: ยื่น Online | K37: ปิดลาออกแล้ว | N37: ลบข้อมูลแล้ว
A38: 37 | B38: MMS660280 | C38: นางสาวสายรุ้ง แม่นวงค์ | D38: 6401 เจ้าหน้าที่ขายและสินเชื่ออาวุโส | E38: เฟล็กซี่ สาทร/เจริญนคร เฟส 1 | F38: sairungm@sena.co.th | G38: 45322 | H38: 45323 | I38: ยกเลิกลาออก | J38: ยกเลิกเอกสาร | K38: ยังไม่ปิดลาออก
A39: 38 | B39: SX670050 | C39: นายธวัช สินสิงห์ | D39: 34 ผู้จัดการโครงการ | E39: ฝ่ายก่อสร้าง 52C | F39: tawats@sena.co.th | G39: 45322 | H39: 45323 | I39: ลาออก | J39: ได้รับเอกสารแล้ว | K39: ปิดลาออกแล้ว | N39: ลบข้อมูลแล้ว
A40: 39 | B40: MMS660335 | C40: นางสาวนฤมล ภูมิสถาน | D40: 5401 ผู้ช่วยหัวหน้างานขาย | E40: เฟล็กซี่ สาทร/เจริญนคร เฟส 1 | F40: naruemonp@sena.co.th | G40: 45322 | H40: 45323 | I40: ลาออก | J40: ยื่น Online | K40: ปิดลาออกแล้ว | N40: ลบข้อมูลแล้ว
A41: 40 | B41: SX670086 | C41: นางสาวมธุรส สุรรัตน์ | D41: 6401 เจ้าหน้าที่ขายและสินเชื่ออาวุโส | E41: เสนา เวล่า สิริโสธร | F41: mathuross@sena.co.th | G41: 45322 | H41: 45323 | I41: ลาออก | J41: ยื่น Online | K41: ปิดลาออกแล้ว | N41: ลบข้อมูลแล้ว
A42: 41 | B42: VMS660037 | C42: นายสุรศักดิ์ ทองบ่อ | D42: 7855 หัวหน้าช่างประจำอาคาร | E42: นิติบุคคล เดอะคิทท์ ฉลองกรุง/ลาดกระบัง | F42: surasakt@sena.co.th | G42: 45322 | H42: 45323 | I42: ลาออก | J42: ยื่น Online | K42: ปิดลาออกแล้ว | N42: ลบข้อมูลแล้ว
A43: 42 | B43: VMS650001 | C43: นายสิทธรัตน์ นุ่มเรือง | D43: 7855 หัวหน้าช่างประจำอาคาร | E43: สายงานบริหารนิติบุคคล | F43: sittaratn@sena.co.th | G43: 45322 | H43: 45323 | I43: ลาออก | J43: ยื่น Online | K43: ปิดลาออกแล้ว | N43: ลบข้อมูลแล้ว
A44: 43 | B44: VMS660046 | C44: นายคมริกรณ์ ธัญมีไชยฉัตร | D44: 7855 หัวหน้าช่างประจำอาคาร | E44: นิติบุคคล คิทท์ ติวานนท์ เฟส 1 | F44: kimrikornt@sena.co.th | G44: 45322 | H44: 45323 | I44: ลาออก | J44: ยื่น Online | K44: ปิดลาออกแล้ว | N44: ลบข้อมูลแล้ว
A45: 44 | B45: MMS660125 | C45: นายภาณุพงษ์ พัวภวเวช | D45: 25 ผู้ช่วยผู้อำนวยการ | E45: สำนักบริหารโครงการ 5 | F45: panupongp@sena.co.th | G45: 45322 | H45: 45323 | I45: ลาออกไม่ครบ 30 วัน | J45: ได้รับเอกสารแล้ว | K45: ปิดลาออกแล้ว | N45: ลบข้อมูลแล้ว
A46: 45 | B46: SX660046 | C46: นายพิสูจน์ สิทธิพรวัฒนากุล | D46: 23 ผู้อำนวยการ | E46: แผนกการขาย | F46: pisuths@senxgroup.com | G46: 45322 | H46: 45323 | I46: ลาออก | J46: ได้รับเอกสารแล้ว | K46: ปิดลาออกแล้ว | N46: ลบข้อมูลแล้ว
A47: 46 | B47: SGA660005 | C47: ว่าที่ ร.ต.เชาวลิต มณีพฤกษ์ | D47: 33 ผู้จัดการ | E47: บริษัท เสนา กรีน ออโตโมทีฟ จำกัด | F47: chaovalitm@sena.co.th | G47: 45322 | H47: 45323 | I47: ลาออก | J47: ได้รับเอกสารแล้ว | K47: ปิดลาออกแล้ว | N47: ลบข้อมูลแล้ว
A48: 47 | B48: MMS660342 | C48: นางสาวจิณัฐตา ทองเดช | D48: 7504 เจ้าหน้าที่ธุรการโครงการ | E48: เสนา วิลล์ บรมราชชนนี สาย 5 | F48: jinattat@sena.co.th | G48: 45322 | H48: 45323 | I48: ลาออกไม่ครบ 30 วัน | J48: ยื่น Online | K48: ปิดลาออกแล้ว | N48: ลบข้อมูลแล้ว
A49: 48 | B49: SD660015 | C49: นางสาวอาทิตยา คุสิตา | D49: 33 ผู้จัดการ | E49: แผนก PR & Media Buy | F49: artitayak@senaidea.com | G49: 45322 | H49: 45323 | I49: ลาออกไม่ครบ 30 วัน | J49: ยื่น Online | K49: ปิดลาออกแล้ว | N49: ลบข้อมูลแล้ว
A50: 49 | B50: SX670089 | C50: นางสาวชณันภัสร์ วิทยมงคลพัชร์ | D50: 7401 เจ้าหน้าที่ขายและสินเชื่อ | E50: เสนา วิลล์ วงแหวน/บางบัวทอง | F50: chananpasw@sena.co.th | G50: 45322 | H50: 45323 | I50: ลาออกไม่ครบ 30 วัน | J50: ยื่น Online | K50: ปิดลาออกแล้ว | N50: ลบข้อมูลแล้ว
A51: 50 | B51: SGA660023 | C51: นางสาวอรวรรณ แสงวัฒนา | D51: 7982 ที่ปรึกษางานด้านการขาย | E51: บริษัท เสนา กรีน ออโตโมทีฟ จำกัด | G51: 45322 | H51: 45323 | I51: ลาออก | J51: ได้รับเอกสารแล้ว | K51: ปิดลาออกแล้ว | N51: ลบข้อมูลแล้ว
A52: 51 | B52: SX670088 | C52: นางสาวรอยพิมพ์ คชาโภชน์ | D52: 6401 เจ้าหน้าที่ขายและสินเชื่ออาวุโส | E52: เสนา วิลล์ วงแหวน/บางบัวทอง | F52: roypimk@sena.co.th | G52: 45326 | H52: 45327 | I52: ลาออกไม่ครบ 30 วัน | J52: ยื่น Online | K52: ปิดลาออกแล้ว | N52: ลบข้อมูลแล้ว
A53: 52 | B53: VMS660040 | C53: นายสมพร ปากดี | D53: 8855 ช่างประจำอาคาร | E53: นิติบุคคล เดอะคิทท์ ฉลองกรุง/ลาดกระบัง | F53: sompronp@sena.co.th | G53: 45327 | H53: 45328 | I53: ลาออกไม่ครบ 30 วัน | J53: ยื่น Online | K53: ปิดลาออกแล้ว | N53: ลบข้อมูลแล้ว
A54: 53 | B54: SX670070 | C54: นางสาวจัสมิน วิศิษฐสงคราม | D54: 7401 เจ้าหน้าที่ขายและสินเชื่อ | E54: เสนา วีว่า ศรีราชา/อัสสัมชัญ | F54: jasminev@sena.co.th | G54: 45330 | H54: 45331 | I54: ลาออกไม่ครบ 30 วัน | J54: ยื่น Online | K54: ปิดลาออกแล้ว | N54: ลบข้อมูลแล้ว
A55: 54 | B55: MMS670030 | C55: นางสาวจุฑามาศ มะกล่ำทอง | D55: 7352 เจ้าหน้าที่ประสานงานโครงการ | E55: สำนักบริหารโครงการ 2 (ก่อสร้าง) | G55: 45330 | H55: 45331 | I55: ปลดออก | J55: ไม่มีเอกสารให้ตรวจสอบ | K55: ปิดลาออกแล้ว | N55: ลบข้อมูลแล้ว
A56: 55 | B56: MMS660056 | C56: นายเอกรัตน์ แก้วศรี | D56: 7502 ช่างสำรวจ | E56: เสนา เวล่า เทพารักษ์/บางบ่อ | F56: ekkaratk@sena.co.th | G56: 45333 | H56: 45334 | I56: ลาออก | J56: ยื่น Online | K56: ปิดลาออกแล้ว | N56: ลบข้อมูลแล้ว
...

Sheet ผู้ใช้งานคอมพิวเตอร์สำนักงานใหญ
G1: Sena ตึก 448
B2: สถานที่ (Site) : อาคารธัญลักษณ์ภาคย์ 448 | C2: Sena Development | D2: Sen-X | G2: ลำดับ | H2: บริษัท | I2: สถานที่ | J2: ชั้น | K2: รหัสพนักงาน | L2: คำนำหน้า (ไทย) | M2: ชื่อ- สกุล (ไทย) | N2: แผนก | O2: PC/NB | P2: Asset Name | Q2: จอ | R2: Asset name
B3: 1 | C3: 2 | G3: 1 | H3: บริษัท เสนาดีเวลลอปเม้นท์ จำกัด (มหาชน) | I3: สถานที่ (Site) : อาคารธัญลักษณ์ภาคย์ (ทรัพย์สินอาคารส่วนกลาง) | J3: 1 | K3: BK620035 | L3: นางสาว | M3: เครือมาศ อินทองปาน | N3: แผนกบริการสำนักงาน | O3: HO0027072C0005 | P3: ชุดคอมพิวเตอร์ All in one
B4: M | C4: 8 | G4: 2 | H4: บริษัท เสนาดีเวลลอปเม้นท์ จำกัด (มหาชน) | I4: สถานที่ (Site) : อาคารธัญลักษณ์ภาคย์ (ทรัพย์สินอาคารส่วนกลาง) | J4: 1 | K4: BK670069 | L4: นางสาว | M4: ลัดดาวัลย์ ปัดพรม | N4: แผนกบริการสำนักงาน | O4: CONHO012C0102 | P4: ชุดคอมพิวเตอร์ CASE (ไม่รวมจอ) | Q4: COMMHO012C0026 | R4: MONITOR LCD 20"
B5: 2 | C5: 41 | D5: 3 | G5: 3 | H5: บริษัท เสนาดีเวลลอปเม้นท์ จำกัด (มหาชน) | I5: สถานที่ (Site) : อาคารธัญลักษณ์ภาคย์ (ฝ่าย IT Support) | J5: 2 | K5: BK650137 | L5: นาย | M5: วรวุฒิ รัตน์นันต์ | N5: สายงานเทคโนโลยีสารสนเทศ | O5: ICTHO012C0444 | P5: NoteBook | Q5: STKICT01000001 | R5: MONITOR LCD 27"
B6: 3 | C6: 56 | G6: 4 | H6: บริษัท เสนาดีเวลลอปเม้นท์ จำกัด (มหาชน) | I6: สถานที่ (Site) : อาคารธัญลักษณ์ภาคย์ (ฝ่ายพัฒนาระบบสารสนเทศ) | J6: 2 | K6: BK650280 | L6: นาย | M6: มลเชียร ทันนาเขตต์ | N6: สายงานเทคโนโลยีสารสนเทศ | O6: HO0007072A0001 | P6: Apple MAC Mini M2 | Q6: HO0007073M0002 | R6: จอคอมพิวเตอร์ FHD HP 27"
B7: 4 | C7: 41 | D7: 1 | G7: 5 | H7: บริษัท เสนาดีเวลลอปเม้นท์ จำกัด (มหาชน) | I7: สถานที่ (Site) : อาคารธัญลักษณ์ภาคย์ (ฝ่าย IT Support) | J7: 2 | K7: BK650136 | L7: นาย | M7: เอกพล ทรัพย์ทวีกานต์ | N7: ฝ่ายพัฒนาระบบสารสนเทศ | O7: HO0033072C0012 | P7: NoteBook | Q7: HO0033073C0057 | R7: จอคอมพิวเตอร์ LED HP 27 นิ้ว
B8: 5 | C8: 35 | D8: 26 | G8: 6 | H8: บริษัท เสนาดีเวลลอปเม้นท์ จำกัด (มหาชน) | I8: สถานที่ (Site) : อาคารธัญลักษณ์ภาคย์ (ฝ่ายพัฒนาระบบสารสนเทศ) | J8: 2 | K8: BK650141 | L8: นาย | M8: สิทธิชัย ดาดาษ | N8: แผนกพัฒนาระบบสารสนเทศ | O8: HO0007072C0038 | P8: Notebook DELL Inspiron 5502 15.6 นิ้ว | Q8: HO2C03021ACC | R8: MONITOR LCD 20"
B9: 6 | C9: 53 | G9: 7 | H9: บริษัท เสนาดีเวลลอปเม้นท์ จำกัด (มหาชน) | I9: สถานที่ (Site) : อาคารธัญลักษณ์ภาคย์ (ฝ่ายพัฒนาระบบสารสนเทศ) | J9: 2 | K9: BK650145 | L9: นาย | M9: วิเชฐ แจ้งดี | N9: ฝ่ายบริหารและสนับสนุนระบบดิจิทัล | O9: CONHO012C0021 | P9: NoteBook | Q9: HO0009072C0014 | R9: MONITOR LCD 27"
B10: 7 | C10: 35 | D10: 1 | G10: 8 | H10: บริษัท เสนาดีเวลลอปเม้นท์ จำกัด (มหาชน) | I10: สถานที่ (Site) : อาคารธัญลักษณ์ภาคย์ (ฝ่าย IT Support) | J10: 2 | K10: BK650143 | L10: นางสาว | M10: รุจิรา น้ำทอง | N10: แผนกบริหารและสนับสนุนระบบดิจิทัล | O10: ICTHO012C0540 | P10: NoteBook | Q10: HO0006073C0004 | R10: จอคอมพิวเตอร์ LED HP 24 นิ้ว
B11: 8 | C11: 40 | G11: 9 | H11: บริษัท เสนาดีเวลลอปเม้นท์ จำกัด (มหาชน) | I11: สถานที่ (Site) : อาคารธัญลักษณ์ภาคย์ (ฝ่ายพัฒนาระบบสารสนเทศ) | J11: 2 | K11: BK650146 | L11: นาย | M11: ธนิสร เย็นประยูรสวัสดิ์ | N11: แผนกบริหารและสนับสนุนระบบดิจิทัล | O11: SALCHANK072C0004 | P11: ชุดคอมพิวเตอร์ CASE (ไม่รวมจอ) | Q11: CONPR2012C0001 | R11: MONITOR LCD 20"
B12: 9 | C12: 70 | G12: 10 | H12: บริษัท เสนาดีเวลลอปเม้นท์ จำกัด (มหาชน) | I12: สถานที่ (Site) : อาคารธัญลักษณ์ภาคย์ (ฝ่ายพัฒนาระบบสารสนเทศ) | J12: 2 | K12: BK650174 | L12: นางสาว | M12: รัชช์ศิร์ บางเจริญพรพงค์ | N12: ฝ่าย Technology และ Analytics | O12: HO0036072N0006 | P12: Notebook DELL Inspiron 3511 15.6" | Q12: HO0007073M0001 | R12: จอคอมพิวเตอร์ FHD HP 27"
B13: 10 | C13: 48 | G13: 11 | H13: บริษัท เสนาดีเวลลอปเม้นท์ จำกัด (มหาชน) | I13: สถานที่ (Site) : อาคารธัญลักษณ์ภาคย์ (ฝ่ายพัฒนาระบบสารสนเทศ) | J13: 2 | K13: BK650283 | L13: นาย | M13: ธนศักดิ์ ซ่อนกลิ่น | N13: ฝ่าย Technology และ Analytics | O13: HO0007072C0039 | P13: Apple MAC Mini M1 | Q13: HO0006073C0005 | R13: จอคอมพิวเตอร์ LED HP 27 นิ้ว
B14: 11 | C14: 12 | G14: 12 | H14: บริษัท เสนาดีเวลลอปเม้นท์ จำกัด (มหาชน) | I14: สถานที่ (Site) : อาคารธัญลักษณ์ภาคย์ (ฝ่ายพัฒนาระบบสารสนเทศ) | J14: 2 | K14: BK650309 | L14: นาย | M14: ณัฐพงศ์ ไหมพรม | N14: ฝ่าย Technology และ Analytics | O14: HO0036072N0044 | P14: Notebook Lenovo ThinkPad E14 Gen2 14" | Q14: HO0007073M0003 | R14: จอคอมพิวเตอร์ FHD HP 27"
B15: 12 | C15: 3 | G15: 13 | H15: บริษัท เสนาดีเวลลอปเม้นท์ จำกัด (มหาชน) | I15: สถานที่ (Site) : อาคารธัญลักษณ์ภาคย์ (ฝ่ายพัฒนาระบบสารสนเทศ) | J15: 2 | K15: BK660107 | L15: นาย | M15: มานิตย์ ศรีคงแก้ว | N15: ฝ่าย Technology และ Analytics | O15: SN:MP2EHAD9 | P15: Notebook Lenovo Thinkbook G3 14" | Q15: SN:9XQD7P3 | R15: จอคอมพิวเตอร์ FHD DELL 27"
B16: รวม | C16: 444 | D16: 31 | G16: 14 | H16: บริษัท เสนาดีเวลลอปเม้นท์ จำกัด (มหาชน) | I16: สถานที่ (Site) : อาคารธัญลักษณ์ภาคย์ (ฝ่ายพัฒนาระบบสารสนเทศ) | J16: 2 | K16: BK660131 | L16: นาย | M16: อดินันท์ อติพิศาลกุล | N16: ฝ่าย Technology และ Analytics | O16: SN:MP2EHW11 | P16: Notebook Lenovo Thinkbook G3 14" | Q16: HO0007073M0004 | R16: จอคอมพิวเตอร์ FHD HP 27"
G17: 15 | H17: บริษัท เสนาดีเวลลอปเม้นท์ จำกัด (มหาชน) | I17: สถานที่ (Site) : อาคารธัญลักษณ์ภาคย์ (ฝ่ายพัฒนาระบบสารสนเทศ) | J17: 2 | K17: BK650139 | L17: นาย | M17: ศุภณัฐ สุขอร่าม | N17: แผนก Technology และ Analytics | O17: SN:PF39GMY4 | P17: Notebook Lenovo V14 GEN2 14" | Q17: CONCKL012C0004 | R17: MONITOR LCD 20"
B18: สถานที่ (Site) : สำนักงานใหญ่ ตึก 522 | C18: Sena Development | D18: Sen-X | G18: 16 | H18: บริษัท เสนาดีเวลลอปเม้นท์ จำกัด (มหาชน) | I18: สถานที่ (Site) : อาคารธัญลักษณ์ภาคย์ (ฝ่ายพัฒนาระบบสารสนเทศ) | J18: 2 | K18: BK660094 | L18: นางสาว | M18: วัชรินทร์ กรพิมาย | N18: แผนก Technology และ Analytics | O18: SN:MP2EJ0P7 | P18: Notebook Lenovo Thinkbook G3 14" | Q18: SN:6M6W3P3 | R18: จอคอมพิวเตอร์ DELL FHD 24"
